{

  "version": 8,
  "blockIdVersion": 10,
  "anchorX": 7,
  "anchorY": 3,
  "anchorZ": 8,
  "blocks": [
    {
      "x": 1,
      "y": 2,
      "z": 2,
      "name": "Rock_Shale_Cobble"
    },
    {
      "x": 1,
      "y": 1,
      "z": 2,
      "name": "Rock_Shale_Cobble"
    },
    {
      "x": 1,
      "y": 0,
      "z": 2,
      "name": "Rock_Shale_Cobble"
    },
    {
      "x": 1,
      "y": 2,
      "z": 3,
      "name": "Rock_Shale_Cobble"
    },
    {
      "x": 1,
      "y": 1,
      "z": 3,
      "name": "Rock_Shale_Cobble"
    },
    {
      "x": 1,
      "y": 0,
      "z": 3,
      "name": "Rock_Shale_Cobble"
    },
    {
      "x": 1,
      "y": 2,
      "z": 4,
      "name": "Rock_Shale_Cobble"
    },
    {
      "x": 1,
      "y": 1,
      "z": 4,
      "name": "Rock_Shale_Cobble"
    },
    {
      "x": 1,
      "y": 0,
      "z": 4,
      "name": "Rock_Shale_Cobble"
    },
    {
      "x": 1,
      "y": 2,
      "z": 12,
      "name": "Rock_Shale_Cobble"
    },
    {
      "x": 1,
      "y": 1,
      "z": 12,
      "name": "Rock_Shale_Cobble"
    },
    {
      "x": 1,
      "y": 0,
      "z": 12,
      "name": "Rock_Shale_Cobble"
    },
    {
      "x": 1,
      "y": 2,
      "z": 13,
      "name": "Rock_Shale_Cobble"
    },
    {
      "x": 1,
      "y": 1,
      "z": 13,
      "name": "Rock_Shale_Cobble"
    },
    {
      "x": 1,
      "y": 0,
      "z": 13,
      "name": "Rock_Shale_Cobble"
    },
    {
      "x": 1,
      "y": 2,
      "z": 14,
      "name": "Rock_Shale_Cobble"
    },
    {
      "x": 1,
      "y": 1,
      "z": 14,
      "name": "Rock_Shale_Cobble"
    },
    {
      "x": 1,
      "y": 0,
      "z": 14,
      "name": "Rock_Shale_Cobble"
    },
    {
      "x": 2,
      "y": 2,
      "z": 2,
      "name": "Rock_Shale_Cobble"
    },
    {
      "x": 2,
      "y": 1,
      "z": 2,
      "name": "Rock_Shale_Cobble"
    },
    {
      "x": 2,
      "y": 0,
      "z": 2,
      "name": "Rock_Shale_Cobble"
    },
    {
      "x": 2,
      "y": 2,
      "z": 3,
      "name": "Rock_Shale_Cobble"
    },
    {
      "x": 2,
      "y": 1,
      "z": 3,
      "name": "Rock_Shale_Cobble"
    },
    {
      "x": 2,
      "y": 0,
      "z": 3,
      "name": "Rock_Shale_Cobble"
    },
    {
      "x": 2,
      "y": 2,
      "z": 4,
      "name": "Rock_Shale_Cobble"
    },
    {
      "x": 2,
      "y": 1,
      "z": 4,
      "name": "Rock_Shale_Cobble"
    },
    {
      "x": 2,
      "y": 0,
      "z": 4,
      "name": "Rock_Shale_Cobble"
    },
    {
      "x": 2,
      "y": 2,
      "z": 5,
      "name": "Rock_Shale_Cobble"
    },
    {
      "x": 2,
      "y": 1,
      "z": 5,
      "name": "Rock_Shale_Cobble"
    },
    {
      "x": 2,
      "y": 0,
      "z": 5,
      "name": "Rock_Shale_Cobble"
    },
    {
      "x": 2,
      "y": 2,
      "z": 6,
      "name": "Rock_Shale_Cobble"
    },
    {
      "x": 2,
      "y": 1,
      "z": 6,
      "name": "Rock_Shale_Cobble"
    },
    {
      "x": 2,
      "y": 0,
      "z": 6,
      "name": "Rock_Shale_Cobble"
    },
    {
      "x": 2,
      "y": 2,
      "z": 7,
      "name": "Rock_Shale_Cobble"
    },
    {
      "x": 2,
      "y": 1,
      "z": 7,
      "name": "Rock_Shale_Cobble"
    },
    {
      "x": 2,
      "y": 0,
      "z": 7,
      "name": "Rock_Shale_Cobble"
    },
    {
      "x": 2,
      "y": 2,
      "z": 8,
      "name": "Rock_Shale_Cobble"
    },
    {
      "x": 2,
      "y": 1,
      "z": 8,
      "name": "Rock_Shale_Cobble"
    },
    {
      "x": 2,
      "y": 0,
      "z": 8,
      "name": "Rock_Shale_Cobble"
    },
    {
      "x": 2,
      "y": 2,
      "z": 9,
      "name": "Rock_Shale_Cobble"
    },
    {
      "x": 2,
      "y": 1,
      "z": 9,
      "name": "Rock_Shale_Cobble"
    },
    {
      "x": 2,
      "y": 0,
      "z": 9,
      "name": "Rock_Shale_Cobble"
    },
    {
      "x": 2,
      "y": 2,
      "z": 10,
      "name": "Rock_Shale_Cobble"
    },
    {
      "x": 2,
      "y": 1,
      "z": 10,
      "name": "Rock_Shale_Cobble"
    },
    {
      "x": 2,
      "y": 0,
      "z": 10,
      "name": "Rock_Shale_Cobble"
    },
    {
      "x": 2,
      "y": 2,
      "z": 11,
      "name": "Rock_Shale_Cobble"
    },
    {
      "x": 2,
      "y": 1,
      "z": 11,
      "name": "Rock_Shale_Cobble"
    },
    {
      "x": 2,
      "y": 0,
      "z": 11,
      "name": "Rock_Shale_Cobble"
    },
    {
      "x": 2,
      "y": 2,
      "z": 12,
      "name": "Rock_Shale_Cobble"
    },
    {
      "x": 2,
      "y": 1,
      "z": 12,
      "name": "Rock_Shale_Cobble"
    },
    {
      "x": 2,
      "y": 0,
      "z": 12,
      "name": "Rock_Shale_Cobble"
    },
    {
      "x": 2,
      "y": 2,
      "z": 13,
      "name": "Rock_Shale_Cobble"
    },
    {
      "x": 2,
      "y": 1,
      "z": 13,
      "name": "Rock_Shale_Cobble"
    },
    {
      "x": 2,
      "y": 0,
      "z": 13,
      "name": "Rock_Shale_Cobble"
    },
    {
      "x": 2,
      "y": 2,
      "z": 14,
      "name": "Rock_Shale_Cobble"
    },
    {
      "x": 2,
      "y": 1,
      "z": 14,
      "name": "Rock_Shale_Cobble"
    },
    {
      "x": 2,
      "y": 0,
      "z": 14,
      "name": "Rock_Shale_Cobble"
    },
    {
      "x": 3,
      "y": 2,
      "z": 2,
      "name": "Rock_Shale_Cobble"
    },
    {
      "x": 3,
      "y": 1,
      "z": 2,
      "name": "Rock_Shale_Cobble"
    },
    {
      "x": 3,
      "y": 0,
      "z": 2,
      "name": "Rock_Shale_Cobble"
    },
    {
      "x": 3,
      "y": 2,
      "z": 3,
      "name": "Rock_Shale_Cobble"
    },
    {
      "x": 3,
      "y": 1,
      "z": 3,
      "name": "Rock_Shale_Cobble"
    },
    {
      "x": 3,
      "y": 0,
      "z": 3,
      "name": "Rock_Shale_Cobble"
    },
    {
      "x": 3,
      "y": 2,
      "z": 4,
      "name": "Rock_Shale_Cobble"
    },
    {
      "x": 3,
      "y": 1,
      "z": 4,
      "name": "Rock_Shale_Cobble"
    },
    {
      "x": 3,
      "y": 0,
      "z": 4,
      "name": "Rock_Shale_Cobble"
    },
    {
      "x": 3,
      "y": 2,
      "z": 5,
      "name": "Rock_Shale_Cobble"
    },
    {
      "x": 3,
      "y": 1,
      "z": 5,
      "name": "Rock_Shale_Cobble"
    },
    {
      "x": 3,
      "y": 0,
      "z": 5,
      "name": "Rock_Shale_Cobble"
    },
    {
      "x": 3,
      "y": 2,
      "z": 6,
      "name": "Rock_Shale_Cobble"
    },
    {
      "x": 3,
      "y": 1,
      "z": 6,
      "name": "Rock_Shale_Cobble"
    },
    {
      "x": 3,
      "y": 0,
      "z": 6,
      "name": "Rock_Shale_Cobble"
    },
    {
      "x": 3,
      "y": 2,
      "z": 7,
      "name": "Rock_Shale_Cobble"
    },
    {
      "x": 3,
      "y": 1,
      "z": 7,
      "name": "Rock_Shale_Cobble"
    },
    {
      "x": 3,
      "y": 0,
      "z": 7,
      "name": "Rock_Shale_Cobble"
    },
    {
      "x": 3,
      "y": 2,
      "z": 8,
      "name": "Rock_Shale_Cobble"
    },
    {
      "x": 3,
      "y": 1,
      "z": 8,
      "name": "Rock_Shale_Cobble"
    },
    {
      "x": 3,
      "y": 0,
      "z": 8,
      "name": "Rock_Shale_Cobble"
    },
    {
      "x": 3,
      "y": 2,
      "z": 9,
      "name": "Rock_Shale_Cobble"
    },
    {
      "x": 3,
      "y": 1,
      "z": 9,
      "name": "Rock_Shale_Cobble"
    },
    {
      "x": 3,
      "y": 0,
      "z": 9,
      "name": "Rock_Shale_Cobble"
    },
    {
      "x": 3,
      "y": 2,
      "z": 10,
      "name": "Rock_Shale_Cobble"
    },
    {
      "x": 3,
      "y": 1,
      "z": 10,
      "name": "Rock_Shale_Cobble"
    },
    {
      "x": 3,
      "y": 0,
      "z": 10,
      "name": "Rock_Shale_Cobble"
    },
    {
      "x": 3,
      "y": 2,
      "z": 11,
      "name": "Rock_Shale_Cobble"
    },
    {
      "x": 3,
      "y": 1,
      "z": 11,
      "name": "Rock_Shale_Cobble"
    },
    {
      "x": 3,
      "y": 0,
      "z": 11,
      "name": "Rock_Shale_Cobble"
    },
    {
      "x": 3,
      "y": 2,
      "z": 12,
      "name": "Rock_Shale_Cobble"
    },
    {
      "x": 3,
      "y": 1,
      "z": 12,
      "name": "Rock_Shale_Cobble"
    },
    {
      "x": 3,
      "y": 0,
      "z": 12,
      "name": "Rock_Shale_Cobble"
    },
    {
      "x": 3,
      "y": 2,
      "z": 13,
      "name": "Rock_Shale_Cobble"
    },
    {
      "x": 3,
      "y": 1,
      "z": 13,
      "name": "Rock_Shale_Cobble"
    },
    {
      "x": 3,
      "y": 0,
      "z": 13,
      "name": "Rock_Shale_Cobble"
    },
    {
      "x": 3,
      "y": 2,
      "z": 14,
      "name": "Rock_Shale_Cobble"
    },
    {
      "x": 3,
      "y": 1,
      "z": 14,
      "name": "Rock_Shale_Cobble"
    },
    {
      "x": 3,
      "y": 0,
      "z": 14,
      "name": "Rock_Shale_Cobble"
    },
    {
      "x": 4,
      "y": 2,
      "z": 3,
      "name": "Rock_Shale_Cobble"
    },
    {
      "x": 4,
      "y": 1,
      "z": 3,
      "name": "Rock_Shale_Cobble"
    },
    {
      "x": 4,
      "y": 0,
      "z": 3,
      "name": "Rock_Shale_Cobble"
    },
    {
      "x": 4,
      "y": 2,
      "z": 4,
      "name": "Rock_Shale_Cobble"
    },
    {
      "x": 4,
      "y": 1,
      "z": 4,
      "name": "Rock_Shale_Cobble"
    },
    {
      "x": 4,
      "y": 0,
      "z": 4,
      "name": "Rock_Shale_Cobble"
    },
    {
      "x": 4,
      "y": 2,
      "z": 5,
      "name": "Rock_Shale_Cobble"
    },
    {
      "x": 4,
      "y": 1,
      "z": 5,
      "name": "Rock_Shale_Cobble"
    },
    {
      "x": 4,
      "y": 0,
      "z": 5,
      "name": "Rock_Shale_Cobble"
    },
    {
      "x": 4,
      "y": 2,
      "z": 6,
      "name": "Rock_Shale_Cobble"
    },
    {
      "x": 4,
      "y": 1,
      "z": 6,
      "name": "Rock_Shale_Cobble"
    },
    {
      "x": 4,
      "y": 0,
      "z": 6,
      "name": "Rock_Shale_Cobble"
    },
    {
      "x": 4,
      "y": 2,
      "z": 7,
      "name": "Rock_Shale_Cobble"
    },
    {
      "x": 4,
      "y": 1,
      "z": 7,
      "name": "Rock_Shale_Cobble"
    },
    {
      "x": 4,
      "y": 0,
      "z": 7,
      "name": "Rock_Shale_Cobble"
    },
    {
      "x": 4,
      "y": 2,
      "z": 8,
      "name": "Rock_Shale_Cobble"
    },
    {
      "x": 4,
      "y": 1,
      "z": 8,
      "name": "Rock_Shale_Cobble"
    },
    {
      "x": 4,
      "y": 0,
      "z": 8,
      "name": "Rock_Shale_Cobble"
    },
    {
      "x": 4,
      "y": 2,
      "z": 9,
      "name": "Rock_Shale_Cobble"
    },
    {
      "x": 4,
      "y": 1,
      "z": 9,
      "name": "Rock_Shale_Cobble"
    },
    {
      "x": 4,
      "y": 0,
      "z": 9,
      "name": "Rock_Shale_Cobble"
    },
    {
      "x": 4,
      "y": 2,
      "z": 10,
      "name": "Rock_Shale_Cobble"
    },
    {
      "x": 4,
      "y": 1,
      "z": 10,
      "name": "Rock_Shale_Cobble"
    },
    {
      "x": 4,
      "y": 0,
      "z": 10,
      "name": "Rock_Shale_Cobble"
    },
    {
      "x": 4,
      "y": 2,
      "z": 11,
      "name": "Rock_Shale_Cobble"
    },
    {
      "x": 4,
      "y": 1,
      "z": 11,
      "name": "Rock_Shale_Cobble"
    },
    {
      "x": 4,
      "y": 0,
      "z": 11,
      "name": "Rock_Shale_Cobble"
    },
    {
      "x": 4,
      "y": 2,
      "z": 12,
      "name": "Rock_Shale_Cobble"
    },
    {
      "x": 4,
      "y": 1,
      "z": 12,
      "name": "Rock_Shale_Cobble"
    },
    {
      "x": 4,
      "y": 0,
      "z": 12,
      "name": "Rock_Shale_Cobble"
    },
    {
      "x": 4,
      "y": 2,
      "z": 13,
      "name": "Rock_Shale_Cobble"
    },
    {
      "x": 4,
      "y": 1,
      "z": 13,
      "name": "Rock_Shale_Cobble"
    },
    {
      "x": 4,
      "y": 0,
      "z": 13,
      "name": "Rock_Shale_Cobble"
    },
    {
      "x": 5,
      "y": 2,
      "z": 3,
      "name": "Rock_Shale_Cobble"
    },
    {
      "x": 5,
      "y": 1,
      "z": 3,
      "name": "Rock_Shale_Cobble"
    },
    {
      "x": 5,
      "y": 0,
      "z": 3,
      "name": "Rock_Shale_Cobble"
    },
    {
      "x": 5,
      "y": 2,
      "z": 4,
      "name": "Rock_Shale_Cobble"
    },
    {
      "x": 5,
      "y": 1,
      "z": 4,
      "name": "Rock_Shale_Cobble"
    },
    {
      "x": 5,
      "y": 0,
      "z": 4,
      "name": "Rock_Shale_Cobble"
    },
    {
      "x": 5,
      "y": 2,
      "z": 5,
      "name": "Rock_Shale_Cobble"
    },
    {
      "x": 5,
      "y": 1,
      "z": 5,
      "name": "Rock_Shale_Cobble"
    },
    {
      "x": 5,
      "y": 0,
      "z": 5,
      "name": "Rock_Shale_Cobble"
    },
    {
      "x": 5,
      "y": 2,
      "z": 6,
      "name": "Rock_Shale_Cobble"
    },
    {
      "x": 5,
      "y": 1,
      "z": 6,
      "name": "Rock_Shale_Cobble"
    },
    {
      "x": 5,
      "y": 0,
      "z": 6,
      "name": "Rock_Shale_Cobble"
    },
    {
      "x": 5,
      "y": 2,
      "z": 7,
      "name": "Rock_Shale_Cobble"
    },
    {
      "x": 5,
      "y": 1,
      "z": 7,
      "name": "Rock_Shale_Cobble"
    },
    {
      "x": 5,
      "y": 0,
      "z": 7,
      "name": "Rock_Shale_Cobble"
    },
    {
      "x": 5,
      "y": 2,
      "z": 8,
      "name": "Rock_Shale_Cobble"
    },
    {
      "x": 5,
      "y": 1,
      "z": 8,
      "name": "Rock_Shale_Cobble"
    },
    {
      "x": 5,
      "y": 0,
      "z": 8,
      "name": "Rock_Shale_Cobble"
    },
    {
      "x": 5,
      "y": 2,
      "z": 9,
      "name": "Rock_Shale_Cobble"
    },
    {
      "x": 5,
      "y": 1,
      "z": 9,
      "name": "Rock_Shale_Cobble"
    },
    {
      "x": 5,
      "y": 0,
      "z": 9,
      "name": "Rock_Shale_Cobble"
    },
    {
      "x": 5,
      "y": 2,
      "z": 10,
      "name": "Rock_Shale_Cobble"
    },
    {
      "x": 5,
      "y": 1,
      "z": 10,
      "name": "Rock_Shale_Cobble"
    },
    {
      "x": 5,
      "y": 0,
      "z": 10,
      "name": "Rock_Shale_Cobble"
    },
    {
      "x": 5,
      "y": 2,
      "z": 11,
      "name": "Rock_Shale_Cobble"
    },
    {
      "x": 5,
      "y": 1,
      "z": 11,
      "name": "Rock_Shale_Cobble"
    },
    {
      "x": 5,
      "y": 0,
      "z": 11,
      "name": "Rock_Shale_Cobble"
    },
    {
      "x": 5,
      "y": 2,
      "z": 12,
      "name": "Rock_Shale_Cobble"
    },
    {
      "x": 5,
      "y": 1,
      "z": 12,
      "name": "Rock_Shale_Cobble"
    },
    {
      "x": 5,
      "y": 0,
      "z": 12,
      "name": "Rock_Shale_Cobble"
    },
    {
      "x": 5,
      "y": 2,
      "z": 13,
      "name": "Rock_Shale_Cobble"
    },
    {
      "x": 5,
      "y": 1,
      "z": 13,
      "name": "Rock_Shale_Cobble"
    },
    {
      "x": 5,
      "y": 0,
      "z": 13,
      "name": "Rock_Shale_Cobble"
    },
    {
      "x": 6,
      "y": 2,
      "z": 3,
      "name": "Rock_Shale_Cobble"
    },
    {
      "x": 6,
      "y": 1,
      "z": 3,
      "name": "Rock_Shale_Cobble"
    },
    {
      "x": 6,
      "y": 0,
      "z": 3,
      "name": "Rock_Shale_Cobble"
    },
    {
      "x": 6,
      "y": 2,
      "z": 4,
      "name": "Rock_Shale_Cobble"
    },
    {
      "x": 6,
      "y": 1,
      "z": 4,
      "name": "Rock_Shale_Cobble"
    },
    {
      "x": 6,
      "y": 0,
      "z": 4,
      "name": "Rock_Shale_Cobble"
    },
    {
      "x": 6,
      "y": 2,
      "z": 5,
      "name": "Rock_Shale_Cobble"
    },
    {
      "x": 6,
      "y": 1,
      "z": 5,
      "name": "Rock_Shale_Cobble"
    },
    {
      "x": 6,
      "y": 0,
      "z": 5,
      "name": "Rock_Shale_Cobble"
    },
    {
      "x": 6,
      "y": 2,
      "z": 6,
      "name": "Rock_Shale_Cobble"
    },
    {
      "x": 6,
      "y": 1,
      "z": 6,
      "name": "Rock_Shale_Cobble"
    },
    {
      "x": 6,
      "y": 0,
      "z": 6,
      "name": "Rock_Shale_Cobble"
    },
    {
      "x": 6,
      "y": 2,
      "z": 7,
      "name": "Rock_Shale_Cobble"
    },
    {
      "x": 6,
      "y": 1,
      "z": 7,
      "name": "Rock_Shale_Cobble"
    },
    {
      "x": 6,
      "y": 0,
      "z": 7,
      "name": "Rock_Shale_Cobble"
    },
    {
      "x": 6,
      "y": 2,
      "z": 8,
      "name": "Rock_Shale_Cobble"
    },
    {
      "x": 6,
      "y": 1,
      "z": 8,
      "name": "Rock_Shale_Cobble"
    },
    {
      "x": 6,
      "y": 0,
      "z": 8,
      "name": "Rock_Shale_Cobble"
    },
    {
      "x": 6,
      "y": 2,
      "z": 9,
      "name": "Rock_Shale_Cobble"
    },
    {
      "x": 6,
      "y": 1,
      "z": 9,
      "name": "Rock_Shale_Cobble"
    },
    {
      "x": 6,
      "y": 0,
      "z": 9,
      "name": "Rock_Shale_Cobble"
    },
    {
      "x": 6,
      "y": 2,
      "z": 10,
      "name": "Rock_Shale_Cobble"
    },
    {
      "x": 6,
      "y": 1,
      "z": 10,
      "name": "Rock_Shale_Cobble"
    },
    {
      "x": 6,
      "y": 0,
      "z": 10,
      "name": "Rock_Shale_Cobble"
    },
    {
      "x": 6,
      "y": 2,
      "z": 11,
      "name": "Rock_Shale_Cobble"
    },
    {
      "x": 6,
      "y": 1,
      "z": 11,
      "name": "Rock_Shale_Cobble"
    },
    {
      "x": 6,
      "y": 0,
      "z": 11,
      "name": "Rock_Shale_Cobble"
    },
    {
      "x": 6,
      "y": 2,
      "z": 12,
      "name": "Rock_Shale_Cobble"
    },
    {
      "x": 6,
      "y": 1,
      "z": 12,
      "name": "Rock_Shale_Cobble"
    },
    {
      "x": 6,
      "y": 0,
      "z": 12,
      "name": "Rock_Shale_Cobble"
    },
    {
      "x": 6,
      "y": 2,
      "z": 13,
      "name": "Rock_Shale_Cobble"
    },
    {
      "x": 6,
      "y": 1,
      "z": 13,
      "name": "Rock_Shale_Cobble"
    },
    {
      "x": 6,
      "y": 0,
      "z": 13,
      "name": "Rock_Shale_Cobble"
    },
    {
      "x": 7,
      "y": 2,
      "z": 3,
      "name": "Rock_Shale_Cobble"
    },
    {
      "x": 7,
      "y": 1,
      "z": 3,
      "name": "Rock_Shale_Cobble"
    },
    {
      "x": 7,
      "y": 0,
      "z": 3,
      "name": "Rock_Shale_Cobble"
    },
    {
      "x": 7,
      "y": 2,
      "z": 4,
      "name": "Rock_Shale_Cobble"
    },
    {
      "x": 7,
      "y": 1,
      "z": 4,
      "name": "Rock_Shale_Cobble"
    },
    {
      "x": 7,
      "y": 0,
      "z": 4,
      "name": "Rock_Shale_Cobble"
    },
    {
      "x": 7,
      "y": 2,
      "z": 5,
      "name": "Rock_Shale_Cobble"
    },
    {
      "x": 7,
      "y": 1,
      "z": 5,
      "name": "Rock_Shale_Cobble"
    },
    {
      "x": 7,
      "y": 0,
      "z": 5,
      "name": "Rock_Shale_Cobble"
    },
    {
      "x": 7,
      "y": 2,
      "z": 6,
      "name": "Rock_Shale_Cobble"
    },
    {
      "x": 7,
      "y": 1,
      "z": 6,
      "name": "Rock_Shale_Cobble"
    },
    {
      "x": 7,
      "y": 0,
      "z": 6,
      "name": "Rock_Shale_Cobble"
    },
    {
      "x": 7,
      "y": 2,
      "z": 7,
      "name": "Rock_Shale_Cobble"
    },
    {
      "x": 7,
      "y": 1,
      "z": 7,
      "name": "Rock_Shale_Cobble"
    },
    {
      "x": 7,
      "y": 0,
      "z": 7,
      "name": "Rock_Shale_Cobble"
    },
    {
      "x": 7,
      "y": 2,
      "z": 8,
      "name": "Rock_Shale_Cobble"
    },
    {
      "x": 7,
      "y": 1,
      "z": 8,
      "name": "Rock_Shale_Cobble"
    },
    {
      "x": 7,
      "y": 0,
      "z": 8,
      "name": "Rock_Shale_Cobble"
    },
    {
      "x": 7,
      "y": 2,
      "z": 9,
      "name": "Rock_Shale_Cobble"
    },
    {
      "x": 7,
      "y": 1,
      "z": 9,
      "name": "Rock_Shale_Cobble"
    },
    {
      "x": 7,
      "y": 0,
      "z": 9,
      "name": "Rock_Shale_Cobble"
    },
    {
      "x": 7,
      "y": 2,
      "z": 10,
      "name": "Rock_Shale_Cobble"
    },
    {
      "x": 7,
      "y": 1,
      "z": 10,
      "name": "Rock_Shale_Cobble"
    },
    {
      "x": 7,
      "y": 0,
      "z": 10,
      "name": "Rock_Shale_Cobble"
    },
    {
      "x": 7,
      "y": 2,
      "z": 11,
      "name": "Rock_Shale_Cobble"
    },
    {
      "x": 7,
      "y": 1,
      "z": 11,
      "name": "Rock_Shale_Cobble"
    },
    {
      "x": 7,
      "y": 0,
      "z": 11,
      "name": "Rock_Shale_Cobble"
    },
    {
      "x": 7,
      "y": 2,
      "z": 12,
      "name": "Rock_Shale_Cobble"
    },
    {
      "x": 7,
      "y": 1,
      "z": 12,
      "name": "Rock_Shale_Cobble"
    },
    {
      "x": 7,
      "y": 0,
      "z": 12,
      "name": "Rock_Shale_Cobble"
    },
    {
      "x": 7,
      "y": 2,
      "z": 13,
      "name": "Rock_Shale_Cobble"
    },
    {
      "x": 7,
      "y": 1,
      "z": 13,
      "name": "Rock_Shale_Cobble"
    },
    {
      "x": 7,
      "y": 0,
      "z": 13,
      "name": "Rock_Shale_Cobble"
    },
    {
      "x": 8,
      "y": 2,
      "z": 3,
      "name": "Rock_Shale_Cobble"
    },
    {
      "x": 8,
      "y": 1,
      "z": 3,
      "name": "Rock_Shale_Cobble"
    },
    {
      "x": 8,
      "y": 0,
      "z": 3,
      "name": "Rock_Shale_Cobble"
    },
    {
      "x": 8,
      "y": 2,
      "z": 4,
      "name": "Rock_Shale_Cobble"
    },
    {
      "x": 8,
      "y": 1,
      "z": 4,
      "name": "Rock_Shale_Cobble"
    },
    {
      "x": 8,
      "y": 0,
      "z": 4,
      "name": "Rock_Shale_Cobble"
    },
    {
      "x": 8,
      "y": 2,
      "z": 5,
      "name": "Rock_Shale_Cobble"
    },
    {
      "x": 8,
      "y": 1,
      "z": 5,
      "name": "Rock_Shale_Cobble"
    },
    {
      "x": 8,
      "y": 0,
      "z": 5,
      "name": "Rock_Shale_Cobble"
    },
    {
      "x": 8,
      "y": 2,
      "z": 6,
      "name": "Rock_Shale_Cobble"
    },
    {
      "x": 8,
      "y": 1,
      "z": 6,
      "name": "Rock_Shale_Cobble"
    },
    {
      "x": 8,
      "y": 0,
      "z": 6,
      "name": "Rock_Shale_Cobble"
    },
    {
      "x": 8,
      "y": 2,
      "z": 7,
      "name": "Rock_Shale_Cobble"
    },
    {
      "x": 8,
      "y": 1,
      "z": 7,
      "name": "Rock_Shale_Cobble"
    },
    {
      "x": 8,
      "y": 0,
      "z": 7,
      "name": "Rock_Shale_Cobble"
    },
    {
      "x": 8,
      "y": 2,
      "z": 8,
      "name": "Rock_Shale_Cobble"
    },
    {
      "x": 8,
      "y": 1,
      "z": 8,
      "name": "Rock_Shale_Cobble"
    },
    {
      "x": 8,
      "y": 0,
      "z": 8,
      "name": "Rock_Shale_Cobble"
    },
    {
      "x": 8,
      "y": 2,
      "z": 9,
      "name": "Rock_Shale_Cobble"
    },
    {
      "x": 8,
      "y": 1,
      "z": 9,
      "name": "Rock_Shale_Cobble"
    },
    {
      "x": 8,
      "y": 0,
      "z": 9,
      "name": "Rock_Shale_Cobble"
    },
    {
      "x": 8,
      "y": 2,
      "z": 10,
      "name": "Rock_Shale_Cobble"
    },
    {
      "x": 8,
      "y": 1,
      "z": 10,
      "name": "Rock_Shale_Cobble"
    },
    {
      "x": 8,
      "y": 0,
      "z": 10,
      "name": "Rock_Shale_Cobble"
    },
    {
      "x": 8,
      "y": 2,
      "z": 11,
      "name": "Rock_Shale_Cobble"
    },
    {
      "x": 8,
      "y": 1,
      "z": 11,
      "name": "Rock_Shale_Cobble"
    },
    {
      "x": 8,
      "y": 0,
      "z": 11,
      "name": "Rock_Shale_Cobble"
    },
    {
      "x": 8,
      "y": 2,
      "z": 12,
      "name": "Rock_Shale_Cobble"
    },
    {
      "x": 8,
      "y": 1,
      "z": 12,
      "name": "Rock_Shale_Cobble"
    },
    {
      "x": 8,
      "y": 0,
      "z": 12,
      "name": "Rock_Shale_Cobble"
    },
    {
      "x": 8,
      "y": 2,
      "z": 13,
      "name": "Rock_Shale_Cobble"
    },
    {
      "x": 8,
      "y": 1,
      "z": 13,
      "name": "Rock_Shale_Cobble"
    },
    {
      "x": 8,
      "y": 0,
      "z": 13,
      "name": "Rock_Shale_Cobble"
    },
    {
      "x": 9,
      "y": 2,
      "z": 3,
      "name": "Rock_Shale_Cobble"
    },
    {
      "x": 9,
      "y": 1,
      "z": 3,
      "name": "Rock_Shale_Cobble"
    },
    {
      "x": 9,
      "y": 0,
      "z": 3,
      "name": "Rock_Shale_Cobble"
    },
    {
      "x": 9,
      "y": 2,
      "z": 4,
      "name": "Rock_Shale_Cobble"
    },
    {
      "x": 9,
      "y": 1,
      "z": 4,
      "name": "Rock_Shale_Cobble"
    },
    {
      "x": 9,
      "y": 0,
      "z": 4,
      "name": "Rock_Shale_Cobble"
    },
    {
      "x": 9,
      "y": 2,
      "z": 5,
      "name": "Rock_Shale_Cobble"
    },
    {
      "x": 9,
      "y": 1,
      "z": 5,
      "name": "Rock_Shale_Cobble"
    },
    {
      "x": 9,
      "y": 0,
      "z": 5,
      "name": "Rock_Shale_Cobble"
    },
    {
      "x": 9,
      "y": 2,
      "z": 6,
      "name": "Rock_Shale_Cobble"
    },
    {
      "x": 9,
      "y": 1,
      "z": 6,
      "name": "Rock_Shale_Cobble"
    },
    {
      "x": 9,
      "y": 0,
      "z": 6,
      "name": "Rock_Shale_Cobble"
    },
    {
      "x": 9,
      "y": 2,
      "z": 7,
      "name": "Rock_Shale_Cobble"
    },
    {
      "x": 9,
      "y": 1,
      "z": 7,
      "name": "Rock_Shale_Cobble"
    },
    {
      "x": 9,
      "y": 0,
      "z": 7,
      "name": "Rock_Shale_Cobble"
    },
    {
      "x": 9,
      "y": 2,
      "z": 8,
      "name": "Rock_Shale_Cobble"
    },
    {
      "x": 9,
      "y": 1,
      "z": 8,
      "name": "Rock_Shale_Cobble"
    },
    {
      "x": 9,
      "y": 0,
      "z": 8,
      "name": "Rock_Shale_Cobble"
    },
    {
      "x": 9,
      "y": 2,
      "z": 9,
      "name": "Rock_Shale_Cobble"
    },
    {
      "x": 9,
      "y": 1,
      "z": 9,
      "name": "Rock_Shale_Cobble"
    },
    {
      "x": 9,
      "y": 0,
      "z": 9,
      "name": "Rock_Shale_Cobble"
    },
    {
      "x": 9,
      "y": 2,
      "z": 10,
      "name": "Rock_Shale_Cobble"
    },
    {
      "x": 9,
      "y": 1,
      "z": 10,
      "name": "Rock_Shale_Cobble"
    },
    {
      "x": 9,
      "y": 0,
      "z": 10,
      "name": "Rock_Shale_Cobble"
    },
    {
      "x": 9,
      "y": 2,
      "z": 11,
      "name": "Rock_Shale_Cobble"
    },
    {
      "x": 9,
      "y": 1,
      "z": 11,
      "name": "Rock_Shale_Cobble"
    },
    {
      "x": 9,
      "y": 0,
      "z": 11,
      "name": "Rock_Shale_Cobble"
    },
    {
      "x": 9,
      "y": 2,
      "z": 12,
      "name": "Rock_Shale_Cobble"
    },
    {
      "x": 9,
      "y": 1,
      "z": 12,
      "name": "Rock_Shale_Cobble"
    },
    {
      "x": 9,
      "y": 0,
      "z": 12,
      "name": "Rock_Shale_Cobble"
    },
    {
      "x": 9,
      "y": 2,
      "z": 13,
      "name": "Rock_Shale_Cobble"
    },
    {
      "x": 9,
      "y": 1,
      "z": 13,
      "name": "Rock_Shale_Cobble"
    },
    {
      "x": 9,
      "y": 0,
      "z": 13,
      "name": "Rock_Shale_Cobble"
    },
    {
      "x": 10,
      "y": 2,
      "z": 3,
      "name": "Rock_Shale_Cobble"
    },
    {
      "x": 10,
      "y": 1,
      "z": 3,
      "name": "Rock_Shale_Cobble"
    },
    {
      "x": 10,
      "y": 0,
      "z": 3,
      "name": "Rock_Shale_Cobble"
    },
    {
      "x": 10,
      "y": 2,
      "z": 4,
      "name": "Rock_Shale_Cobble"
    },
    {
      "x": 10,
      "y": 1,
      "z": 4,
      "name": "Rock_Shale_Cobble"
    },
    {
      "x": 10,
      "y": 0,
      "z": 4,
      "name": "Rock_Shale_Cobble"
    },
    {
      "x": 10,
      "y": 2,
      "z": 5,
      "name": "Rock_Shale_Cobble"
    },
    {
      "x": 10,
      "y": 1,
      "z": 5,
      "name": "Rock_Shale_Cobble"
    },
    {
      "x": 10,
      "y": 0,
      "z": 5,
      "name": "Rock_Shale_Cobble"
    },
    {
      "x": 10,
      "y": 2,
      "z": 6,
      "name": "Rock_Shale_Cobble"
    },
    {
      "x": 10,
      "y": 1,
      "z": 6,
      "name": "Rock_Shale_Cobble"
    },
    {
      "x": 10,
      "y": 0,
      "z": 6,
      "name": "Rock_Shale_Cobble"
    },
    {
      "x": 10,
      "y": 2,
      "z": 7,
      "name": "Rock_Shale_Cobble"
    },
    {
      "x": 10,
      "y": 1,
      "z": 7,
      "name": "Rock_Shale_Cobble"
    },
    {
      "x": 10,
      "y": 0,
      "z": 7,
      "name": "Rock_Shale_Cobble"
    },
    {
      "x": 10,
      "y": 2,
      "z": 8,
      "name": "Rock_Shale_Cobble"
    },
    {
      "x": 10,
      "y": 1,
      "z": 8,
      "name": "Rock_Shale_Cobble"
    },
    {
      "x": 10,
      "y": 0,
      "z": 8,
      "name": "Rock_Shale_Cobble"
    },
    {
      "x": 10,
      "y": 2,
      "z": 9,
      "name": "Rock_Shale_Cobble"
    },
    {
      "x": 10,
      "y": 1,
      "z": 9,
      "name": "Rock_Shale_Cobble"
    },
    {
      "x": 10,
      "y": 0,
      "z": 9,
      "name": "Rock_Shale_Cobble"
    },
    {
      "x": 10,
      "y": 2,
      "z": 10,
      "name": "Rock_Shale_Cobble"
    },
    {
      "x": 10,
      "y": 1,
      "z": 10,
      "name": "Rock_Shale_Cobble"
    },
    {
      "x": 10,
      "y": 0,
      "z": 10,
      "name": "Rock_Shale_Cobble"
    },
    {
      "x": 10,
      "y": 2,
      "z": 11,
      "name": "Rock_Shale_Cobble"
    },
    {
      "x": 10,
      "y": 1,
      "z": 11,
      "name": "Rock_Shale_Cobble"
    },
    {
      "x": 10,
      "y": 0,
      "z": 11,
      "name": "Rock_Shale_Cobble"
    },
    {
      "x": 10,
      "y": 2,
      "z": 12,
      "name": "Rock_Shale_Cobble"
    },
    {
      "x": 10,
      "y": 1,
      "z": 12,
      "name": "Rock_Shale_Cobble"
    },
    {
      "x": 10,
      "y": 0,
      "z": 12,
      "name": "Rock_Shale_Cobble"
    },
    {
      "x": 10,
      "y": 2,
      "z": 13,
      "name": "Rock_Shale_Cobble"
    },
    {
      "x": 10,
      "y": 1,
      "z": 13,
      "name": "Rock_Shale_Cobble"
    },
    {
      "x": 10,
      "y": 0,
      "z": 13,
      "name": "Rock_Shale_Cobble"
    },
    {
      "x": 11,
      "y": 2,
      "z": 2,
      "name": "Rock_Shale_Cobble"
    },
    {
      "x": 11,
      "y": 1,
      "z": 2,
      "name": "Rock_Shale_Cobble"
    },
    {
      "x": 11,
      "y": 0,
      "z": 2,
      "name": "Rock_Shale_Cobble"
    },
    {
      "x": 11,
      "y": 2,
      "z": 3,
      "name": "Rock_Shale_Cobble"
    },
    {
      "x": 11,
      "y": 1,
      "z": 3,
      "name": "Rock_Shale_Cobble"
    },
    {
      "x": 11,
      "y": 0,
      "z": 3,
      "name": "Rock_Shale_Cobble"
    },
    {
      "x": 11,
      "y": 2,
      "z": 4,
      "name": "Rock_Shale_Cobble"
    },
    {
      "x": 11,
      "y": 1,
      "z": 4,
      "name": "Rock_Shale_Cobble"
    },
    {
      "x": 11,
      "y": 0,
      "z": 4,
      "name": "Rock_Shale_Cobble"
    },
    {
      "x": 11,
      "y": 2,
      "z": 5,
      "name": "Rock_Shale_Cobble"
    },
    {
      "x": 11,
      "y": 1,
      "z": 5,
      "name": "Rock_Shale_Cobble"
    },
    {
      "x": 11,
      "y": 0,
      "z": 5,
      "name": "Rock_Shale_Cobble"
    },
    {
      "x": 11,
      "y": 2,
      "z": 6,
      "name": "Rock_Shale_Cobble"
    },
    {
      "x": 11,
      "y": 1,
      "z": 6,
      "name": "Rock_Shale_Cobble"
    },
    {
      "x": 11,
      "y": 0,
      "z": 6,
      "name": "Rock_Shale_Cobble"
    },
    {
      "x": 11,
      "y": 2,
      "z": 7,
      "name": "Rock_Shale_Cobble"
    },
    {
      "x": 11,
      "y": 1,
      "z": 7,
      "name": "Rock_Shale_Cobble"
    },
    {
      "x": 11,
      "y": 0,
      "z": 7,
      "name": "Rock_Shale_Cobble"
    },
    {
      "x": 11,
      "y": 2,
      "z": 8,
      "name": "Rock_Shale_Cobble"
    },
    {
      "x": 11,
      "y": 1,
      "z": 8,
      "name": "Rock_Shale_Cobble"
    },
    {
      "x": 11,
      "y": 0,
      "z": 8,
      "name": "Rock_Shale_Cobble"
    },
    {
      "x": 11,
      "y": 2,
      "z": 9,
      "name": "Rock_Shale_Cobble"
    },
    {
      "x": 11,
      "y": 1,
      "z": 9,
      "name": "Rock_Shale_Cobble"
    },
    {
      "x": 11,
      "y": 0,
      "z": 9,
      "name": "Rock_Shale_Cobble"
    },
    {
      "x": 11,
      "y": 2,
      "z": 10,
      "name": "Rock_Shale_Cobble"
    },
    {
      "x": 11,
      "y": 1,
      "z": 10,
      "name": "Rock_Shale_Cobble"
    },
    {
      "x": 11,
      "y": 0,
      "z": 10,
      "name": "Rock_Shale_Cobble"
    },
    {
      "x": 11,
      "y": 2,
      "z": 11,
      "name": "Rock_Shale_Cobble"
    },
    {
      "x": 11,
      "y": 1,
      "z": 11,
      "name": "Rock_Shale_Cobble"
    },
    {
      "x": 11,
      "y": 0,
      "z": 11,
      "name": "Rock_Shale_Cobble"
    },
    {
      "x": 11,
      "y": 2,
      "z": 12,
      "name": "Rock_Shale_Cobble"
    },
    {
      "x": 11,
      "y": 1,
      "z": 12,
      "name": "Rock_Shale_Cobble"
    },
    {
      "x": 11,
      "y": 0,
      "z": 12,
      "name": "Rock_Shale_Cobble"
    },
    {
      "x": 11,
      "y": 2,
      "z": 13,
      "name": "Rock_Shale_Cobble"
    },
    {
      "x": 11,
      "y": 1,
      "z": 13,
      "name": "Rock_Shale_Cobble"
    },
    {
      "x": 11,
      "y": 0,
      "z": 13,
      "name": "Rock_Shale_Cobble"
    },
    {
      "x": 11,
      "y": 2,
      "z": 14,
      "name": "Rock_Shale_Cobble"
    },
    {
      "x": 11,
      "y": 1,
      "z": 14,
      "name": "Rock_Shale_Cobble"
    },
    {
      "x": 11,
      "y": 0,
      "z": 14,
      "name": "Rock_Shale_Cobble"
    },
    {
      "x": 12,
      "y": 2,
      "z": 2,
      "name": "Rock_Shale_Cobble"
    },
    {
      "x": 12,
      "y": 1,
      "z": 2,
      "name": "Rock_Shale_Cobble"
    },
    {
      "x": 12,
      "y": 0,
      "z": 2,
      "name": "Rock_Shale_Cobble"
    },
    {
      "x": 12,
      "y": 2,
      "z": 3,
      "name": "Rock_Shale_Cobble"
    },
    {
      "x": 12,
      "y": 1,
      "z": 3,
      "name": "Rock_Shale_Cobble"
    },
    {
      "x": 12,
      "y": 0,
      "z": 3,
      "name": "Rock_Shale_Cobble"
    },
    {
      "x": 12,
      "y": 2,
      "z": 4,
      "name": "Rock_Shale_Cobble"
    },
    {
      "x": 12,
      "y": 1,
      "z": 4,
      "name": "Rock_Shale_Cobble"
    },
    {
      "x": 12,
      "y": 0,
      "z": 4,
      "name": "Rock_Shale_Cobble"
    },
    {
      "x": 12,
      "y": 2,
      "z": 5,
      "name": "Rock_Shale_Cobble"
    },
    {
      "x": 12,
      "y": 1,
      "z": 5,
      "name": "Rock_Shale_Cobble"
    },
    {
      "x": 12,
      "y": 0,
      "z": 5,
      "name": "Rock_Shale_Cobble"
    },
    {
      "x": 12,
      "y": 2,
      "z": 6,
      "name": "Rock_Shale_Cobble"
    },
    {
      "x": 12,
      "y": 1,
      "z": 6,
      "name": "Rock_Shale_Cobble"
    },
    {
      "x": 12,
      "y": 0,
      "z": 6,
      "name": "Rock_Shale_Cobble"
    },
    {
      "x": 12,
      "y": 2,
      "z": 7,
      "name": "Rock_Shale_Cobble"
    },
    {
      "x": 12,
      "y": 1,
      "z": 7,
      "name": "Rock_Shale_Cobble"
    },
    {
      "x": 12,
      "y": 0,
      "z": 7,
      "name": "Rock_Shale_Cobble"
    },
    {
      "x": 12,
      "y": 2,
      "z": 8,
      "name": "Rock_Shale_Cobble"
    },
    {
      "x": 12,
      "y": 1,
      "z": 8,
      "name": "Rock_Shale_Cobble"
    },
    {
      "x": 12,
      "y": 0,
      "z": 8,
      "name": "Rock_Shale_Cobble"
    },
    {
      "x": 12,
      "y": 2,
      "z": 9,
      "name": "Rock_Shale_Cobble"
    },
    {
      "x": 12,
      "y": 1,
      "z": 9,
      "name": "Rock_Shale_Cobble"
    },
    {
      "x": 12,
      "y": 0,
      "z": 9,
      "name": "Rock_Shale_Cobble"
    },
    {
      "x": 12,
      "y": 2,
      "z": 10,
      "name": "Rock_Shale_Cobble"
    },
    {
      "x": 12,
      "y": 1,
      "z": 10,
      "name": "Rock_Shale_Cobble"
    },
    {
      "x": 12,
      "y": 0,
      "z": 10,
      "name": "Rock_Shale_Cobble"
    },
    {
      "x": 12,
      "y": 2,
      "z": 11,
      "name": "Rock_Shale_Cobble"
    },
    {
      "x": 12,
      "y": 1,
      "z": 11,
      "name": "Rock_Shale_Cobble"
    },
    {
      "x": 12,
      "y": 0,
      "z": 11,
      "name": "Rock_Shale_Cobble"
    },
    {
      "x": 12,
      "y": 2,
      "z": 12,
      "name": "Rock_Shale_Cobble"
    },
    {
      "x": 12,
      "y": 1,
      "z": 12,
      "name": "Rock_Shale_Cobble"
    },
    {
      "x": 12,
      "y": 0,
      "z": 12,
      "name": "Rock_Shale_Cobble"
    },
    {
      "x": 12,
      "y": 2,
      "z": 13,
      "name": "Rock_Shale_Cobble"
    },
    {
      "x": 12,
      "y": 1,
      "z": 13,
      "name": "Rock_Shale_Cobble"
    },
    {
      "x": 12,
      "y": 0,
      "z": 13,
      "name": "Rock_Shale_Cobble"
    },
    {
      "x": 12,
      "y": 2,
      "z": 14,
      "name": "Rock_Shale_Cobble"
    },
    {
      "x": 12,
      "y": 1,
      "z": 14,
      "name": "Rock_Shale_Cobble"
    },
    {
      "x": 12,
      "y": 0,
      "z": 14,
      "name": "Rock_Shale_Cobble"
    },
    {
      "x": 13,
      "y": 2,
      "z": 2,
      "name": "Rock_Shale_Cobble"
    },
    {
      "x": 13,
      "y": 1,
      "z": 2,
      "name": "Rock_Shale_Cobble"
    },
    {
      "x": 13,
      "y": 0,
      "z": 2,
      "name": "Rock_Shale_Cobble"
    },
    {
      "x": 13,
      "y": 2,
      "z": 3,
      "name": "Rock_Shale_Cobble"
    },
    {
      "x": 13,
      "y": 1,
      "z": 3,
      "name": "Rock_Shale_Cobble"
    },
    {
      "x": 13,
      "y": 0,
      "z": 3,
      "name": "Rock_Shale_Cobble"
    },
    {
      "x": 13,
      "y": 2,
      "z": 4,
      "name": "Rock_Shale_Cobble"
    },
    {
      "x": 13,
      "y": 1,
      "z": 4,
      "name": "Rock_Shale_Cobble"
    },
    {
      "x": 13,
      "y": 0,
      "z": 4,
      "name": "Rock_Shale_Cobble"
    },
    {
      "x": 13,
      "y": 2,
      "z": 12,
      "name": "Rock_Shale_Cobble"
    },
    {
      "x": 13,
      "y": 1,
      "z": 12,
      "name": "Rock_Shale_Cobble"
    },
    {
      "x": 13,
      "y": 0,
      "z": 12,
      "name": "Rock_Shale_Cobble"
    },
    {
      "x": 13,
      "y": 2,
      "z": 13,
      "name": "Rock_Shale_Cobble"
    },
    {
      "x": 13,
      "y": 1,
      "z": 13,
      "name": "Rock_Shale_Cobble"
    },
    {
      "x": 13,
      "y": 0,
      "z": 13,
      "name": "Rock_Shale_Cobble"
    },
    {
      "x": 13,
      "y": 2,
      "z": 14,
      "name": "Rock_Shale_Cobble"
    },
    {
      "x": 13,
      "y": 1,
      "z": 14,
      "name": "Rock_Shale_Cobble"
    },
    {
      "x": 13,
      "y": 0,
      "z": 14,
      "name": "Rock_Shale_Cobble"
    },
    {
      "x": 6,
      "y": 2,
      "z": 14,
      "name": "Rock_Shale_Cobble"
    },
    {
      "x": 6,
      "y": 3,
      "z": 14,
      "name": "Rock_Shale_Cobble_Stairs",
      "rotation": 0
    },
    {
      "x": 7,
      "y": 2,
      "z": 14,
      "name": "Rock_Shale_Cobble"
    },
    {
      "x": 7,
      "y": 3,
      "z": 14,
      "name": "Rock_Shale_Cobble_Stairs",
      "rotation": 0
    },
    {
      "x": 8,
      "y": 2,
      "z": 14,
      "name": "Rock_Shale_Cobble"
    },
    {
      "x": 8,
      "y": 3,
      "z": 14,
      "name": "Rock_Shale_Cobble_Stairs",
      "rotation": 0
    },
    {
      "x": 2,
      "y": 3,
      "z": 3,
      "name": "Rock_Shale_Brick"
    },
    {
      "x": 2,
      "y": 3,
      "z": 4,
      "name": "Rock_Shale_Brick"
    },
    {
      "x": 2,
      "y": 3,
      "z": 5,
      "name": "Rock_Shale_Brick"
    },
    {
      "x": 2,
      "y": 3,
      "z": 6,
      "name": "Rock_Shale_Brick"
    },
    {
      "x": 2,
      "y": 3,
      "z": 7,
      "name": "Rock_Shale_Brick"
    },
    {
      "x": 2,
      "y": 3,
      "z": 8,
      "name": "Rock_Shale_Brick"
    },
    {
      "x": 2,
      "y": 3,
      "z": 9,
      "name": "Rock_Shale_Brick"
    },
    {
      "x": 2,
      "y": 3,
      "z": 10,
      "name": "Rock_Shale_Brick"
    },
    {
      "x": 2,
      "y": 3,
      "z": 11,
      "name": "Rock_Shale_Brick"
    },
    {
      "x": 2,
      "y": 3,
      "z": 12,
      "name": "Rock_Shale_Brick"
    },
    {
      "x": 2,
      "y": 3,
      "z": 13,
      "name": "Rock_Shale_Brick"
    },
    {
      "x": 3,
      "y": 3,
      "z": 3,
      "name": "Rock_Shale_Brick"
    },
    {
      "x": 3,
      "y": 3,
      "z": 4,
      "name": "Rock_Shale_Brick"
    },
    {
      "x": 3,
      "y": 3,
      "z": 5,
      "name": "Rock_Shale_Brick"
    },
    {
      "x": 3,
      "y": 3,
      "z": 6,
      "name": "Rock_Shale_Brick"
    },
    {
      "x": 3,
      "y": 3,
      "z": 7,
      "name": "Rock_Shale_Brick"
    },
    {
      "x": 3,
      "y": 3,
      "z": 8,
      "name": "Rock_Shale_Brick"
    },
    {
      "x": 3,
      "y": 3,
      "z": 9,
      "name": "Rock_Shale_Brick"
    },
    {
      "x": 3,
      "y": 3,
      "z": 10,
      "name": "Rock_Shale_Brick"
    },
    {
      "x": 3,
      "y": 3,
      "z": 11,
      "name": "Rock_Shale_Brick"
    },
    {
      "x": 3,
      "y": 3,
      "z": 12,
      "name": "Rock_Shale_Brick"
    },
    {
      "x": 3,
      "y": 3,
      "z": 13,
      "name": "Rock_Shale_Brick"
    },
    {
      "x": 4,
      "y": 3,
      "z": 3,
      "name": "Rock_Shale_Brick"
    },
    {
      "x": 4,
      "y": 3,
      "z": 4,
      "name": "Rock_Shale_Brick"
    },
    {
      "x": 4,
      "y": 3,
      "z": 5,
      "name": "Rock_Shale_Brick"
    },
    {
      "x": 4,
      "y": 3,
      "z": 6,
      "name": "Rock_Shale_Brick"
    },
    {
      "x": 4,
      "y": 3,
      "z": 7,
      "name": "Rock_Shale_Brick"
    },
    {
      "x": 4,
      "y": 3,
      "z": 8,
      "name": "Rock_Shale_Brick"
    },
    {
      "x": 4,
      "y": 3,
      "z": 9,
      "name": "Rock_Shale_Brick"
    },
    {
      "x": 4,
      "y": 3,
      "z": 10,
      "name": "Rock_Shale_Brick"
    },
    {
      "x": 4,
      "y": 3,
      "z": 11,
      "name": "Rock_Shale_Brick"
    },
    {
      "x": 4,
      "y": 3,
      "z": 12,
      "name": "Rock_Shale_Brick"
    },
    {
      "x": 4,
      "y": 3,
      "z": 13,
      "name": "Rock_Shale_Brick"
    },
    {
      "x": 5,
      "y": 3,
      "z": 3,
      "name": "Rock_Shale_Brick"
    },
    {
      "x": 5,
      "y": 3,
      "z": 4,
      "name": "Rock_Shale_Brick"
    },
    {
      "x": 5,
      "y": 3,
      "z": 5,
      "name": "Rock_Shale_Brick"
    },
    {
      "x": 5,
      "y": 3,
      "z": 6,
      "name": "Rock_Shale_Brick"
    },
    {
      "x": 5,
      "y": 3,
      "z": 7,
      "name": "Rock_Shale_Brick"
    },
    {
      "x": 5,
      "y": 3,
      "z": 8,
      "name": "Rock_Shale_Brick"
    },
    {
      "x": 5,
      "y": 3,
      "z": 9,
      "name": "Rock_Shale_Brick"
    },
    {
      "x": 5,
      "y": 3,
      "z": 10,
      "name": "Rock_Shale_Brick"
    },
    {
      "x": 5,
      "y": 3,
      "z": 11,
      "name": "Rock_Shale_Brick"
    },
    {
      "x": 5,
      "y": 3,
      "z": 12,
      "name": "Rock_Shale_Brick"
    },
    {
      "x": 5,
      "y": 3,
      "z": 13,
      "name": "Rock_Shale_Brick"
    },
    {
      "x": 6,
      "y": 3,
      "z": 3,
      "name": "Rock_Shale_Brick"
    },
    {
      "x": 6,
      "y": 3,
      "z": 4,
      "name": "Rock_Shale_Brick"
    },
    {
      "x": 6,
      "y": 3,
      "z": 5,
      "name": "Rock_Shale_Brick"
    },
    {
      "x": 6,
      "y": 3,
      "z": 6,
      "name": "Rock_Shale_Brick"
    },
    {
      "x": 6,
      "y": 3,
      "z": 7,
      "name": "Rock_Shale_Brick"
    },
    {
      "x": 6,
      "y": 3,
      "z": 8,
      "name": "Rock_Shale_Brick"
    },
    {
      "x": 6,
      "y": 3,
      "z": 9,
      "name": "Rock_Shale_Brick"
    },
    {
      "x": 6,
      "y": 3,
      "z": 10,
      "name": "Rock_Shale_Brick"
    },
    {
      "x": 6,
      "y": 3,
      "z": 11,
      "name": "Rock_Shale_Brick"
    },
    {
      "x": 6,
      "y": 3,
      "z": 12,
      "name": "Rock_Shale_Brick"
    },
    {
      "x": 6,
      "y": 3,
      "z": 13,
      "name": "Rock_Shale_Brick"
    },
    {
      "x": 7,
      "y": 3,
      "z": 3,
      "name": "Rock_Shale_Brick"
    },
    {
      "x": 7,
      "y": 3,
      "z": 4,
      "name": "Rock_Shale_Brick"
    },
    {
      "x": 7,
      "y": 3,
      "z": 5,
      "name": "Rock_Shale_Brick"
    },
    {
      "x": 7,
      "y": 3,
      "z": 6,
      "name": "Rock_Shale_Brick"
    },
    {
      "x": 7,
      "y": 3,
      "z": 7,
      "name": "Rock_Shale_Brick"
    },
    {
      "x": 7,
      "y": 3,
      "z": 8,
      "name": "Rock_Shale_Brick"
    },
    {
      "x": 7,
      "y": 3,
      "z": 9,
      "name": "Rock_Shale_Brick"
    },
    {
      "x": 7,
      "y": 3,
      "z": 10,
      "name": "Rock_Shale_Brick"
    },
    {
      "x": 7,
      "y": 3,
      "z": 11,
      "name": "Rock_Shale_Brick"
    },
    {
      "x": 7,
      "y": 3,
      "z": 12,
      "name": "Rock_Shale_Brick"
    },
    {
      "x": 7,
      "y": 3,
      "z": 13,
      "name": "Rock_Shale_Brick"
    },
    {
      "x": 8,
      "y": 3,
      "z": 3,
      "name": "Rock_Shale_Brick"
    },
    {
      "x": 8,
      "y": 3,
      "z": 4,
      "name": "Rock_Shale_Brick"
    },
    {
      "x": 8,
      "y": 3,
      "z": 5,
      "name": "Rock_Shale_Brick"
    },
    {
      "x": 8,
      "y": 3,
      "z": 6,
      "name": "Rock_Shale_Brick"
    },
    {
      "x": 8,
      "y": 3,
      "z": 7,
      "name": "Rock_Shale_Brick"
    },
    {
      "x": 8,
      "y": 3,
      "z": 8,
      "name": "Rock_Shale_Brick"
    },
    {
      "x": 8,
      "y": 3,
      "z": 9,
      "name": "Rock_Shale_Brick"
    },
    {
      "x": 8,
      "y": 3,
      "z": 10,
      "name": "Rock_Shale_Brick"
    },
    {
      "x": 8,
      "y": 3,
      "z": 11,
      "name": "Rock_Shale_Brick"
    },
    {
      "x": 8,
      "y": 3,
      "z": 12,
      "name": "Rock_Shale_Brick"
    },
    {
      "x": 8,
      "y": 3,
      "z": 13,
      "name": "Rock_Shale_Brick"
    },
    {
      "x": 9,
      "y": 3,
      "z": 3,
      "name": "Rock_Shale_Brick"
    },
    {
      "x": 9,
      "y": 3,
      "z": 4,
      "name": "Rock_Shale_Brick"
    },
    {
      "x": 9,
      "y": 3,
      "z": 5,
      "name": "Rock_Shale_Brick"
    },
    {
      "x": 9,
      "y": 3,
      "z": 6,
      "name": "Rock_Shale_Brick"
    },
    {
      "x": 9,
      "y": 3,
      "z": 7,
      "name": "Rock_Shale_Brick"
    },
    {
      "x": 9,
      "y": 3,
      "z": 8,
      "name": "Rock_Shale_Brick"
    },
    {
      "x": 9,
      "y": 3,
      "z": 9,
      "name": "Rock_Shale_Brick"
    },
    {
      "x": 9,
      "y": 3,
      "z": 10,
      "name": "Rock_Shale_Brick"
    },
    {
      "x": 9,
      "y": 3,
      "z": 11,
      "name": "Rock_Shale_Brick"
    },
    {
      "x": 9,
      "y": 3,
      "z": 12,
      "name": "Rock_Shale_Brick"
    },
    {
      "x": 9,
      "y": 3,
      "z": 13,
      "name": "Rock_Shale_Brick"
    },
    {
      "x": 10,
      "y": 3,
      "z": 3,
      "name": "Rock_Shale_Brick"
    },
    {
      "x": 10,
      "y": 3,
      "z": 4,
      "name": "Rock_Shale_Brick"
    },
    {
      "x": 10,
      "y": 3,
      "z": 5,
      "name": "Rock_Shale_Brick"
    },
    {
      "x": 10,
      "y": 3,
      "z": 6,
      "name": "Rock_Shale_Brick"
    },
    {
      "x": 10,
      "y": 3,
      "z": 7,
      "name": "Rock_Shale_Brick"
    },
    {
      "x": 10,
      "y": 3,
      "z": 8,
      "name": "Rock_Shale_Brick"
    },
    {
      "x": 10,
      "y": 3,
      "z": 9,
      "name": "Rock_Shale_Brick"
    },
    {
      "x": 10,
      "y": 3,
      "z": 10,
      "name": "Rock_Shale_Brick"
    },
    {
      "x": 10,
      "y": 3,
      "z": 11,
      "name": "Rock_Shale_Brick"
    },
    {
      "x": 10,
      "y": 3,
      "z": 12,
      "name": "Rock_Shale_Brick"
    },
    {
      "x": 10,
      "y": 3,
      "z": 13,
      "name": "Rock_Shale_Brick"
    },
    {
      "x": 11,
      "y": 3,
      "z": 3,
      "name": "Rock_Shale_Brick"
    },
    {
      "x": 11,
      "y": 3,
      "z": 4,
      "name": "Rock_Shale_Brick"
    },
    {
      "x": 11,
      "y": 3,
      "z": 5,
      "name": "Rock_Shale_Brick"
    },
    {
      "x": 11,
      "y": 3,
      "z": 6,
      "name": "Rock_Shale_Brick"
    },
    {
      "x": 11,
      "y": 3,
      "z": 7,
      "name": "Rock_Shale_Brick"
    },
    {
      "x": 11,
      "y": 3,
      "z": 8,
      "name": "Rock_Shale_Brick"
    },
    {
      "x": 11,
      "y": 3,
      "z": 9,
      "name": "Rock_Shale_Brick"
    },
    {
      "x": 11,
      "y": 3,
      "z": 10,
      "name": "Rock_Shale_Brick"
    },
    {
      "x": 11,
      "y": 3,
      "z": 11,
      "name": "Rock_Shale_Brick"
    },
    {
      "x": 11,
      "y": 3,
      "z": 12,
      "name": "Rock_Shale_Brick"
    },
    {
      "x": 11,
      "y": 3,
      "z": 13,
      "name": "Rock_Shale_Brick"
    },
    {
      "x": 12,
      "y": 3,
      "z": 3,
      "name": "Rock_Shale_Brick"
    },
    {
      "x": 12,
      "y": 3,
      "z": 4,
      "name": "Rock_Shale_Brick"
    },
    {
      "x": 12,
      "y": 3,
      "z": 5,
      "name": "Rock_Shale_Brick"
    },
    {
      "x": 12,
      "y": 3,
      "z": 6,
      "name": "Rock_Shale_Brick"
    },
    {
      "x": 12,
      "y": 3,
      "z": 7,
      "name": "Rock_Shale_Brick"
    },
    {
      "x": 12,
      "y": 3,
      "z": 8,
      "name": "Rock_Shale_Brick"
    },
    {
      "x": 12,
      "y": 3,
      "z": 9,
      "name": "Rock_Shale_Brick"
    },
    {
      "x": 12,
      "y": 3,
      "z": 10,
      "name": "Rock_Shale_Brick"
    },
    {
      "x": 12,
      "y": 3,
      "z": 11,
      "name": "Rock_Shale_Brick"
    },
    {
      "x": 12,
      "y": 3,
      "z": 12,
      "name": "Rock_Shale_Brick"
    },
    {
      "x": 12,
      "y": 3,
      "z": 13,
      "name": "Rock_Shale_Brick"
    },
    {
      "x": 1,
      "y": 3,
      "z": 2,
      "name": "Rock_Shale_Brick"
    },
    {
      "x": 1,
      "y": 3,
      "z": 3,
      "name": "Rock_Shale_Brick"
    },
    {
      "x": 1,
      "y": 3,
      "z": 4,
      "name": "Rock_Shale_Brick"
    },
    {
      "x": 2,
      "y": 3,
      "z": 2,
      "name": "Rock_Shale_Brick"
    },
    {
      "x": 3,
      "y": 3,
      "z": 2,
      "name": "Rock_Shale_Brick"
    },
    {
      "x": 1,
      "y": 3,
      "z": 12,
      "name": "Rock_Shale_Brick"
    },
    {
      "x": 1,
      "y": 3,
      "z": 13,
      "name": "Rock_Shale_Brick"
    },
    {
      "x": 1,
      "y": 3,
      "z": 14,
      "name": "Rock_Shale_Brick"
    },
    {
      "x": 2,
      "y": 3,
      "z": 14,
      "name": "Rock_Shale_Brick"
    },
    {
      "x": 3,
      "y": 3,
      "z": 14,
      "name": "Rock_Shale_Brick"
    },
    {
      "x": 11,
      "y": 3,
      "z": 2,
      "name": "Rock_Shale_Brick"
    },
    {
      "x": 12,
      "y": 3,
      "z": 2,
      "name": "Rock_Shale_Brick"
    },
    {
      "x": 13,
      "y": 3,
      "z": 2,
      "name": "Rock_Shale_Brick"
    },
    {
      "x": 13,
      "y": 3,
      "z": 3,
      "name": "Rock_Shale_Brick"
    },
    {
      "x": 13,
      "y": 3,
      "z": 4,
      "name": "Rock_Shale_Brick"
    },
    {
      "x": 11,
      "y": 3,
      "z": 14,
      "name": "Rock_Shale_Brick"
    },
    {
      "x": 12,
      "y": 3,
      "z": 14,
      "name": "Rock_Shale_Brick"
    },
    {
      "x": 13,
      "y": 3,
      "z": 12,
      "name": "Rock_Shale_Brick"
    },
    {
      "x": 13,
      "y": 3,
      "z": 13,
      "name": "Rock_Shale_Brick"
    },
    {
      "x": 13,
      "y": 3,
      "z": 14,
      "name": "Rock_Shale_Brick"
    },
    {
      "x": 2,
      "y": 4,
      "z": 3,
      "name": "Rock_Shale_Brick_Pillar_Base"
    },
    {
      "x": 2,
      "y": 4,
      "z": 4,
      "name": "Rock_Shale_Cobble"
    },
    {
      "x": 2,
      "y": 4,
      "z": 5,
      "name": "Rock_Shale_Cobble"
    },
    {
      "x": 2,
      "y": 4,
      "z": 6,
      "name": "Rock_Shale_Cobble"
    },
    {
      "x": 2,
      "y": 4,
      "z": 7,
      "name": "Rock_Shale_Cobble"
    },
    {
      "x": 2,
      "y": 4,
      "z": 8,
      "name": "Rock_Shale_Cobble"
    },
    {
      "x": 2,
      "y": 4,
      "z": 9,
      "name": "Rock_Shale_Cobble"
    },
    {
      "x": 2,
      "y": 4,
      "z": 10,
      "name": "Rock_Shale_Cobble"
    },
    {
      "x": 2,
      "y": 4,
      "z": 11,
      "name": "Rock_Shale_Cobble"
    },
    {
      "x": 2,
      "y": 4,
      "z": 12,
      "name": "Rock_Shale_Cobble"
    },
    {
      "x": 2,
      "y": 4,
      "z": 13,
      "name": "Rock_Shale_Brick_Pillar_Base"
    },
    {
      "x": 3,
      "y": 4,
      "z": 3,
      "name": "Rock_Shale_Cobble"
    },
    {
      "x": 3,
      "y": 4,
      "z": 13,
      "name": "Rock_Shale_Cobble"
    },
    {
      "x": 4,
      "y": 4,
      "z": 3,
      "name": "Rock_Shale_Cobble"
    },
    {
      "x": 4,
      "y": 4,
      "z": 13,
      "name": "Rock_Shale_Cobble"
    },
    {
      "x": 5,
      "y": 4,
      "z": 3,
      "name": "Rock_Shale_Cobble"
    },
    {
      "x": 5,
      "y": 4,
      "z": 13,
      "name": "Rock_Shale_Cobble"
    },
    {
      "x": 6,
      "y": 4,
      "z": 3,
      "name": "Rock_Shale_Cobble"
    },
    {
      "x": 7,
      "y": 4,
      "z": 3,
      "name": "Rock_Shale_Cobble"
    },
    {
      "x": 8,
      "y": 4,
      "z": 3,
      "name": "Rock_Shale_Cobble"
    },
    {
      "x": 9,
      "y": 4,
      "z": 3,
      "name": "Rock_Shale_Cobble"
    },
    {
      "x": 9,
      "y": 4,
      "z": 13,
      "name": "Rock_Shale_Cobble"
    },
    {
      "x": 10,
      "y": 4,
      "z": 3,
      "name": "Rock_Shale_Cobble"
    },
    {
      "x": 10,
      "y": 4,
      "z": 13,
      "name": "Rock_Shale_Cobble"
    },
    {
      "x": 11,
      "y": 4,
      "z": 3,
      "name": "Rock_Shale_Cobble"
    },
    {
      "x": 11,
      "y": 4,
      "z": 13,
      "name": "Rock_Shale_Cobble"
    },
    {
      "x": 12,
      "y": 4,
      "z": 3,
      "name": "Rock_Shale_Brick_Pillar_Base"
    },
    {
      "x": 12,
      "y": 4,
      "z": 4,
      "name": "Rock_Shale_Cobble"
    },
    {
      "x": 12,
      "y": 4,
      "z": 5,
      "name": "Rock_Shale_Cobble"
    },
    {
      "x": 12,
      "y": 4,
      "z": 6,
      "name": "Rock_Shale_Cobble"
    },
    {
      "x": 12,
      "y": 4,
      "z": 7,
      "name": "Rock_Shale_Cobble"
    },
    {
      "x": 12,
      "y": 4,
      "z": 8,
      "name": "Rock_Shale_Cobble"
    },
    {
      "x": 12,
      "y": 4,
      "z": 9,
      "name": "Rock_Shale_Cobble"
    },
    {
      "x": 12,
      "y": 4,
      "z": 10,
      "name": "Rock_Shale_Cobble"
    },
    {
      "x": 12,
      "y": 4,
      "z": 11,
      "name": "Rock_Shale_Cobble"
    },
    {
      "x": 12,
      "y": 4,
      "z": 12,
      "name": "Rock_Shale_Cobble"
    },
    {
      "x": 12,
      "y": 4,
      "z": 13,
      "name": "Rock_Shale_Brick_Pillar_Base"
    },
    {
      "x": 1,
      "y": 4,
      "z": 2,
      "name": "Rock_Shale_Brick_Pillar_Base"
    },
    {
      "x": 1,
      "y": 4,
      "z": 3,
      "name": "Rock_Shale_Cobble"
    },
    {
      "x": 1,
      "y": 4,
      "z": 4,
      "name": "Rock_Shale_Cobble"
    },
    {
      "x": 2,
      "y": 4,
      "z": 2,
      "name": "Rock_Shale_Cobble"
    },
    {
      "x": 3,
      "y": 4,
      "z": 2,
      "name": "Rock_Shale_Cobble"
    },
    {
      "x": 1,
      "y": 4,
      "z": 12,
      "name": "Rock_Shale_Cobble"
    },
    {
      "x": 1,
      "y": 4,
      "z": 13,
      "name": "Rock_Shale_Cobble"
    },
    {
      "x": 1,
      "y": 4,
      "z": 14,
      "name": "Rock_Shale_Brick_Pillar_Base"
    },
    {
      "x": 2,
      "y": 4,
      "z": 14,
      "name": "Rock_Shale_Cobble"
    },
    {
      "x": 3,
      "y": 4,
      "z": 14,
      "name": "Rock_Shale_Cobble"
    },
    {
      "x": 11,
      "y": 4,
      "z": 2,
      "name": "Rock_Shale_Cobble"
    },
    {
      "x": 12,
      "y": 4,
      "z": 2,
      "name": "Rock_Shale_Cobble"
    },
    {
      "x": 13,
      "y": 4,
      "z": 2,
      "name": "Rock_Shale_Brick_Pillar_Base"
    },
    {
      "x": 13,
      "y": 4,
      "z": 3,
      "name": "Rock_Shale_Cobble"
    },
    {
      "x": 13,
      "y": 4,
      "z": 4,
      "name": "Rock_Shale_Cobble"
    },
    {
      "x": 11,
      "y": 4,
      "z": 14,
      "name": "Rock_Shale_Cobble"
    },
    {
      "x": 12,
      "y": 4,
      "z": 14,
      "name": "Rock_Shale_Cobble"
    },
    {
      "x": 13,
      "y": 4,
      "z": 12,
      "name": "Rock_Shale_Cobble"
    },
    {
      "x": 13,
      "y": 4,
      "z": 13,
      "name": "Rock_Shale_Cobble"
    },
    {
      "x": 13,
      "y": 4,
      "z": 14,
      "name": "Rock_Shale_Brick_Pillar_Base"
    },
    {
      "x": 2,
      "y": 5,
      "z": 3,
      "name": "Rock_Shale_Brick_Pillar_Base"
    },
    {
      "x": 2,
      "y": 5,
      "z": 4,
      "name": "Rock_Shale_Cobble"
    },
    {
      "x": 2,
      "y": 5,
      "z": 5,
      "name": "Rock_Shale_Cobble"
    },
    {
      "x": 2,
      "y": 5,
      "z": 7,
      "name": "Rock_Shale_Cobble"
    },
    {
      "x": 2,
      "y": 5,
      "z": 8,
      "name": "Rock_Shale_Cobble"
    },
    {
      "x": 2,
      "y": 5,
      "z": 9,
      "name": "Rock_Shale_Cobble"
    },
    {
      "x": 2,
      "y": 5,
      "z": 11,
      "name": "Rock_Shale_Cobble"
    },
    {
      "x": 2,
      "y": 5,
      "z": 12,
      "name": "Rock_Shale_Cobble"
    },
    {
      "x": 2,
      "y": 5,
      "z": 13,
      "name": "Rock_Shale_Brick_Pillar_Base"
    },
    {
      "x": 3,
      "y": 5,
      "z": 3,
      "name": "Rock_Shale_Cobble"
    },
    {
      "x": 3,
      "y": 5,
      "z": 13,
      "name": "Rock_Shale_Cobble"
    },
    {
      "x": 4,
      "y": 5,
      "z": 3,
      "name": "Rock_Shale_Cobble"
    },
    {
      "x": 4,
      "y": 5,
      "z": 13,
      "name": "Rock_Shale_Cobble"
    },
    {
      "x": 5,
      "y": 5,
      "z": 13,
      "name": "Rock_Shale_Cobble"
    },
    {
      "x": 6,
      "y": 5,
      "z": 3,
      "name": "Rock_Shale_Cobble"
    },
    {
      "x": 7,
      "y": 5,
      "z": 3,
      "name": "Rock_Shale_Cobble"
    },
    {
      "x": 8,
      "y": 5,
      "z": 3,
      "name": "Rock_Shale_Cobble"
    },
    {
      "x": 9,
      "y": 5,
      "z": 13,
      "name": "Rock_Shale_Cobble"
    },
    {
      "x": 10,
      "y": 5,
      "z": 3,
      "name": "Rock_Shale_Cobble"
    },
    {
      "x": 10,
      "y": 5,
      "z": 13,
      "name": "Rock_Shale_Cobble"
    },
    {
      "x": 11,
      "y": 5,
      "z": 3,
      "name": "Rock_Shale_Cobble"
    },
    {
      "x": 11,
      "y": 5,
      "z": 13,
      "name": "Rock_Shale_Cobble"
    },
    {
      "x": 12,
      "y": 5,
      "z": 3,
      "name": "Rock_Shale_Brick_Pillar_Base"
    },
    {
      "x": 12,
      "y": 5,
      "z": 4,
      "name": "Rock_Shale_Cobble"
    },
    {
      "x": 12,
      "y": 5,
      "z": 5,
      "name": "Rock_Shale_Cobble"
    },
    {
      "x": 12,
      "y": 5,
      "z": 7,
      "name": "Rock_Shale_Cobble"
    },
    {
      "x": 12,
      "y": 5,
      "z": 8,
      "name": "Rock_Shale_Cobble"
    },
    {
      "x": 12,
      "y": 5,
      "z": 9,
      "name": "Rock_Shale_Cobble"
    },
    {
      "x": 12,
      "y": 5,
      "z": 11,
      "name": "Rock_Shale_Cobble"
    },
    {
      "x": 12,
      "y": 5,
      "z": 12,
      "name": "Rock_Shale_Cobble"
    },
    {
      "x": 12,
      "y": 5,
      "z": 13,
      "name": "Rock_Shale_Brick_Pillar_Base"
    },
    {
      "x": 1,
      "y": 5,
      "z": 2,
      "name": "Rock_Shale_Brick_Pillar_Base"
    },
    {
      "x": 1,
      "y": 5,
      "z": 3,
      "name": "Rock_Shale_Cobble"
    },
    {
      "x": 1,
      "y": 5,
      "z": 4,
      "name": "Rock_Shale_Cobble"
    },
    {
      "x": 2,
      "y": 5,
      "z": 2,
      "name": "Rock_Shale_Cobble"
    },
    {
      "x": 3,
      "y": 5,
      "z": 2,
      "name": "Rock_Shale_Cobble"
    },
    {
      "x": 1,
      "y": 5,
      "z": 12,
      "name": "Rock_Shale_Cobble"
    },
    {
      "x": 1,
      "y": 5,
      "z": 13,
      "name": "Rock_Shale_Cobble"
    },
    {
      "x": 1,
      "y": 5,
      "z": 14,
      "name": "Rock_Shale_Brick_Pillar_Base"
    },
    {
      "x": 2,
      "y": 5,
      "z": 14,
      "name": "Rock_Shale_Cobble"
    },
    {
      "x": 3,
      "y": 5,
      "z": 14,
      "name": "Rock_Shale_Cobble"
    },
    {
      "x": 11,
      "y": 5,
      "z": 2,
      "name": "Rock_Shale_Cobble"
    },
    {
      "x": 12,
      "y": 5,
      "z": 2,
      "name": "Rock_Shale_Cobble"
    },
    {
      "x": 13,
      "y": 5,
      "z": 2,
      "name": "Rock_Shale_Brick_Pillar_Base"
    },
    {
      "x": 13,
      "y": 5,
      "z": 3,
      "name": "Rock_Shale_Cobble"
    },
    {
      "x": 13,
      "y": 5,
      "z": 4,
      "name": "Rock_Shale_Cobble"
    },
    {
      "x": 11,
      "y": 5,
      "z": 14,
      "name": "Rock_Shale_Cobble"
    },
    {
      "x": 12,
      "y": 5,
      "z": 14,
      "name": "Rock_Shale_Cobble"
    },
    {
      "x": 13,
      "y": 5,
      "z": 12,
      "name": "Rock_Shale_Cobble"
    },
    {
      "x": 13,
      "y": 5,
      "z": 13,
      "name": "Rock_Shale_Cobble"
    },
    {
      "x": 13,
      "y": 5,
      "z": 14,
      "name": "Rock_Shale_Brick_Pillar_Base"
    },
    {
      "x": 2,
      "y": 6,
      "z": 3,
      "name": "Rock_Shale_Brick_Pillar_Base"
    },
    {
      "x": 2,
      "y": 6,
      "z": 4,
      "name": "Rock_Shale_Cobble"
    },
    {
      "x": 2,
      "y": 6,
      "z": 5,
      "name": "Rock_Shale_Cobble"
    },
    {
      "x": 2,
      "y": 6,
      "z": 7,
      "name": "Rock_Shale_Cobble"
    },
    {
      "x": 2,
      "y": 6,
      "z": 8,
      "name": "Rock_Shale_Cobble"
    },
    {
      "x": 2,
      "y": 6,
      "z": 9,
      "name": "Rock_Shale_Cobble"
    },
    {
      "x": 2,
      "y": 6,
      "z": 11,
      "name": "Rock_Shale_Cobble"
    },
    {
      "x": 2,
      "y": 6,
      "z": 12,
      "name": "Rock_Shale_Cobble"
    },
    {
      "x": 2,
      "y": 6,
      "z": 13,
      "name": "Rock_Shale_Brick_Pillar_Base"
    },
    {
      "x": 3,
      "y": 6,
      "z": 3,
      "name": "Rock_Shale_Cobble"
    },
    {
      "x": 3,
      "y": 6,
      "z": 13,
      "name": "Rock_Shale_Cobble"
    },
    {
      "x": 4,
      "y": 6,
      "z": 3,
      "name": "Rock_Shale_Cobble"
    },
    {
      "x": 4,
      "y": 6,
      "z": 13,
      "name": "Rock_Shale_Cobble"
    },
    {
      "x": 5,
      "y": 6,
      "z": 13,
      "name": "Rock_Shale_Cobble"
    },
    {
      "x": 6,
      "y": 6,
      "z": 3,
      "name": "Rock_Shale_Cobble"
    },
    {
      "x": 7,
      "y": 6,
      "z": 3,
      "name": "Rock_Shale_Cobble"
    },
    {
      "x": 8,
      "y": 6,
      "z": 3,
      "name": "Rock_Shale_Cobble"
    },
    {
      "x": 9,
      "y": 6,
      "z": 13,
      "name": "Rock_Shale_Cobble"
    },
    {
      "x": 10,
      "y": 6,
      "z": 3,
      "name": "Rock_Shale_Cobble"
    },
    {
      "x": 10,
      "y": 6,
      "z": 13,
      "name": "Rock_Shale_Cobble"
    },
    {
      "x": 11,
      "y": 6,
      "z": 3,
      "name": "Rock_Shale_Cobble"
    },
    {
      "x": 11,
      "y": 6,
      "z": 13,
      "name": "Rock_Shale_Cobble"
    },
    {
      "x": 12,
      "y": 6,
      "z": 3,
      "name": "Rock_Shale_Brick_Pillar_Base"
    },
    {
      "x": 12,
      "y": 6,
      "z": 4,
      "name": "Rock_Shale_Cobble"
    },
    {
      "x": 12,
      "y": 6,
      "z": 5,
      "name": "Rock_Shale_Cobble"
    },
    {
      "x": 12,
      "y": 6,
      "z": 7,
      "name": "Rock_Shale_Cobble"
    },
    {
      "x": 12,
      "y": 6,
      "z": 8,
      "name": "Rock_Shale_Cobble"
    },
    {
      "x": 12,
      "y": 6,
      "z": 9,
      "name": "Rock_Shale_Cobble"
    },
    {
      "x": 12,
      "y": 6,
      "z": 11,
      "name": "Rock_Shale_Cobble"
    },
    {
      "x": 12,
      "y": 6,
      "z": 12,
      "name": "Rock_Shale_Cobble"
    },
    {
      "x": 12,
      "y": 6,
      "z": 13,
      "name": "Rock_Shale_Brick_Pillar_Base"
    },
    {
      "x": 1,
      "y": 6,
      "z": 2,
      "name": "Rock_Shale_Brick_Pillar_Base"
    },
    {
      "x": 1,
      "y": 6,
      "z": 3,
      "name": "Rock_Shale_Cobble"
    },
    {
      "x": 1,
      "y": 6,
      "z": 4,
      "name": "Rock_Shale_Cobble"
    },
    {
      "x": 2,
      "y": 6,
      "z": 2,
      "name": "Rock_Shale_Cobble"
    },
    {
      "x": 3,
      "y": 6,
      "z": 2,
      "name": "Rock_Shale_Cobble"
    },
    {
      "x": 1,
      "y": 6,
      "z": 12,
      "name": "Rock_Shale_Cobble"
    },
    {
      "x": 1,
      "y": 6,
      "z": 13,
      "name": "Rock_Shale_Cobble"
    },
    {
      "x": 1,
      "y": 6,
      "z": 14,
      "name": "Rock_Shale_Brick_Pillar_Base"
    },
    {
      "x": 2,
      "y": 6,
      "z": 14,
      "name": "Rock_Shale_Cobble"
    },
    {
      "x": 3,
      "y": 6,
      "z": 14,
      "name": "Rock_Shale_Cobble"
    },
    {
      "x": 11,
      "y": 6,
      "z": 2,
      "name": "Rock_Shale_Cobble"
    },
    {
      "x": 12,
      "y": 6,
      "z": 2,
      "name": "Rock_Shale_Cobble"
    },
    {
      "x": 13,
      "y": 6,
      "z": 2,
      "name": "Rock_Shale_Brick_Pillar_Base"
    },
    {
      "x": 13,
      "y": 6,
      "z": 3,
      "name": "Rock_Shale_Cobble"
    },
    {
      "x": 13,
      "y": 6,
      "z": 4,
      "name": "Rock_Shale_Cobble"
    },
    {
      "x": 11,
      "y": 6,
      "z": 14,
      "name": "Rock_Shale_Cobble"
    },
    {
      "x": 12,
      "y": 6,
      "z": 14,
      "name": "Rock_Shale_Cobble"
    },
    {
      "x": 13,
      "y": 6,
      "z": 12,
      "name": "Rock_Shale_Cobble"
    },
    {
      "x": 13,
      "y": 6,
      "z": 13,
      "name": "Rock_Shale_Cobble"
    },
    {
      "x": 13,
      "y": 6,
      "z": 14,
      "name": "Rock_Shale_Brick_Pillar_Base"
    },
    {
      "x": 2,
      "y": 7,
      "z": 3,
      "name": "Rock_Shale_Brick_Pillar_Base"
    },
    {
      "x": 2,
      "y": 7,
      "z": 4,
      "name": "Rock_Shale_Cobble"
    },
    {
      "x": 2,
      "y": 7,
      "z": 5,
      "name": "Rock_Shale_Cobble"
    },
    {
      "x": 2,
      "y": 7,
      "z": 6,
      "name": "Rock_Shale_Cobble"
    },
    {
      "x": 2,
      "y": 7,
      "z": 7,
      "name": "Rock_Shale_Cobble"
    },
    {
      "x": 2,
      "y": 7,
      "z": 8,
      "name": "Rock_Shale_Cobble"
    },
    {
      "x": 2,
      "y": 7,
      "z": 9,
      "name": "Rock_Shale_Cobble"
    },
    {
      "x": 2,
      "y": 7,
      "z": 10,
      "name": "Rock_Shale_Cobble"
    },
    {
      "x": 2,
      "y": 7,
      "z": 11,
      "name": "Rock_Shale_Cobble"
    },
    {
      "x": 2,
      "y": 7,
      "z": 12,
      "name": "Rock_Shale_Cobble"
    },
    {
      "x": 2,
      "y": 7,
      "z": 13,
      "name": "Rock_Shale_Brick_Pillar_Base"
    },
    {
      "x": 3,
      "y": 7,
      "z": 3,
      "name": "Rock_Shale_Cobble"
    },
    {
      "x": 3,
      "y": 7,
      "z": 13,
      "name": "Rock_Shale_Cobble"
    },
    {
      "x": 4,
      "y": 7,
      "z": 3,
      "name": "Rock_Shale_Cobble"
    },
    {
      "x": 4,
      "y": 7,
      "z": 13,
      "name": "Rock_Shale_Cobble"
    },
    {
      "x": 5,
      "y": 7,
      "z": 3,
      "name": "Rock_Shale_Cobble"
    },
    {
      "x": 5,
      "y": 7,
      "z": 13,
      "name": "Rock_Shale_Cobble"
    },
    {
      "x": 6,
      "y": 7,
      "z": 3,
      "name": "Rock_Shale_Cobble"
    },
    {
      "x": 6,
      "y": 7,
      "z": 13,
      "name": "Rock_Shale_Cobble"
    },
    {
      "x": 7,
      "y": 7,
      "z": 3,
      "name": "Rock_Shale_Cobble"
    },
    {
      "x": 7,
      "y": 7,
      "z": 13,
      "name": "Rock_Shale_Cobble"
    },
    {
      "x": 8,
      "y": 7,
      "z": 3,
      "name": "Rock_Shale_Cobble"
    },
    {
      "x": 8,
      "y": 7,
      "z": 13,
      "name": "Rock_Shale_Cobble"
    },
    {
      "x": 9,
      "y": 7,
      "z": 3,
      "name": "Rock_Shale_Cobble"
    },
    {
      "x": 9,
      "y": 7,
      "z": 13,
      "name": "Rock_Shale_Cobble"
    },
    {
      "x": 10,
      "y": 7,
      "z": 3,
      "name": "Rock_Shale_Cobble"
    },
    {
      "x": 10,
      "y": 7,
      "z": 13,
      "name": "Rock_Shale_Cobble"
    },
    {
      "x": 11,
      "y": 7,
      "z": 3,
      "name": "Rock_Shale_Cobble"
    },
    {
      "x": 11,
      "y": 7,
      "z": 13,
      "name": "Rock_Shale_Cobble"
    },
    {
      "x": 12,
      "y": 7,
      "z": 3,
      "name": "Rock_Shale_Brick_Pillar_Base"
    },
    {
      "x": 12,
      "y": 7,
      "z": 4,
      "name": "Rock_Shale_Cobble"
    },
    {
      "x": 12,
      "y": 7,
      "z": 5,
      "name": "Rock_Shale_Cobble"
    },
    {
      "x": 12,
      "y": 7,
      "z": 6,
      "name": "Rock_Shale_Cobble"
    },
    {
      "x": 12,
      "y": 7,
      "z": 7,
      "name": "Rock_Shale_Cobble"
    },
    {
      "x": 12,
      "y": 7,
      "z": 8,
      "name": "Rock_Shale_Cobble"
    },
    {
      "x": 12,
      "y": 7,
      "z": 9,
      "name": "Rock_Shale_Cobble"
    },
    {
      "x": 12,
      "y": 7,
      "z": 10,
      "name": "Rock_Shale_Cobble"
    },
    {
      "x": 12,
      "y": 7,
      "z": 11,
      "name": "Rock_Shale_Cobble"
    },
    {
      "x": 12,
      "y": 7,
      "z": 12,
      "name": "Rock_Shale_Cobble"
    },
    {
      "x": 12,
      "y": 7,
      "z": 13,
      "name": "Rock_Shale_Brick_Pillar_Base"
    },
    {
      "x": 1,
      "y": 7,
      "z": 2,
      "name": "Rock_Shale_Brick_Pillar_Base"
    },
    {
      "x": 1,
      "y": 7,
      "z": 3,
      "name": "Rock_Shale_Cobble"
    },
    {
      "x": 1,
      "y": 7,
      "z": 4,
      "name": "Rock_Shale_Cobble"
    },
    {
      "x": 2,
      "y": 7,
      "z": 2,
      "name": "Rock_Shale_Cobble"
    },
    {
      "x": 3,
      "y": 7,
      "z": 2,
      "name": "Rock_Shale_Cobble"
    },
    {
      "x": 1,
      "y": 7,
      "z": 12,
      "name": "Rock_Shale_Cobble"
    },
    {
      "x": 1,
      "y": 7,
      "z": 13,
      "name": "Rock_Shale_Cobble"
    },
    {
      "x": 1,
      "y": 7,
      "z": 14,
      "name": "Rock_Shale_Brick_Pillar_Base"
    },
    {
      "x": 2,
      "y": 7,
      "z": 14,
      "name": "Rock_Shale_Cobble"
    },
    {
      "x": 3,
      "y": 7,
      "z": 14,
      "name": "Rock_Shale_Cobble"
    },
    {
      "x": 11,
      "y": 7,
      "z": 2,
      "name": "Rock_Shale_Cobble"
    },
    {
      "x": 12,
      "y": 7,
      "z": 2,
      "name": "Rock_Shale_Cobble"
    },
    {
      "x": 13,
      "y": 7,
      "z": 2,
      "name": "Rock_Shale_Brick_Pillar_Base"
    },
    {
      "x": 13,
      "y": 7,
      "z": 3,
      "name": "Rock_Shale_Cobble"
    },
    {
      "x": 13,
      "y": 7,
      "z": 4,
      "name": "Rock_Shale_Cobble"
    },
    {
      "x": 11,
      "y": 7,
      "z": 14,
      "name": "Rock_Shale_Cobble"
    },
    {
      "x": 12,
      "y": 7,
      "z": 14,
      "name": "Rock_Shale_Cobble"
    },
    {
      "x": 13,
      "y": 7,
      "z": 12,
      "name": "Rock_Shale_Cobble"
    },
    {
      "x": 13,
      "y": 7,
      "z": 13,
      "name": "Rock_Shale_Cobble"
    },
    {
      "x": 13,
      "y": 7,
      "z": 14,
      "name": "Rock_Shale_Brick_Pillar_Base"
    },
    {
      "x": 11,
      "y": 4,
      "z": 5,
      "name": "Rock_Shale_Cobble_Stairs",
      "rotation": 2
    },
    {
      "x": 10,
      "y": 4,
      "z": 5,
      "name": "Rock_Shale_Cobble_Stairs",
      "rotation": 2
    },
    {
      "x": 11,
      "y": 5,
      "z": 6,
      "name": "Rock_Shale_Cobble_Stairs",
      "rotation": 2
    },
    {
      "x": 10,
      "y": 5,
      "z": 6,
      "name": "Rock_Shale_Cobble_Stairs",
      "rotation": 2
    },
    {
      "x": 11,
      "y": 6,
      "z": 7,
      "name": "Rock_Shale_Cobble_Stairs",
      "rotation": 2
    },
    {
      "x": 10,
      "y": 6,
      "z": 7,
      "name": "Rock_Shale_Cobble_Stairs",
      "rotation": 2
    },
    {
      "x": 11,
      "y": 7,
      "z": 8,
      "name": "Rock_Shale_Cobble_Stairs",
      "rotation": 2
    },
    {
      "x": 10,
      "y": 7,
      "z": 8,
      "name": "Rock_Shale_Cobble_Stairs",
      "rotation": 2
    },
    {
      "x": 7,
      "y": 4,
      "z": 4,
      "name": "Furniture_Ancient_Torch"
    },
    {
      "x": 7,
      "y": 4,
      "z": 12,
      "name": "Furniture_Ancient_Torch"
    },
    {
      "x": 11,
      "y": 4,
      "z": 8,
      "name": "Furniture_Ancient_Torch"
    },
    {
      "x": 3,
      "y": 4,
      "z": 8,
      "name": "Furniture_Ancient_Torch"
    },
    {
      "x": 2,
      "y": 8,
      "z": 3,
      "name": "Rock_Shale_Brick"
    },
    {
      "x": 2,
      "y": 8,
      "z": 4,
      "name": "Rock_Shale_Brick"
    },
    {
      "x": 2,
      "y": 8,
      "z": 5,
      "name": "Rock_Shale_Brick"
    },
    {
      "x": 2,
      "y": 8,
      "z": 6,
      "name": "Rock_Shale_Brick"
    },
    {
      "x": 2,
      "y": 8,
      "z": 7,
      "name": "Rock_Shale_Brick"
    },
    {
      "x": 2,
      "y": 8,
      "z": 8,
      "name": "Rock_Shale_Brick"
    },
    {
      "x": 2,
      "y": 8,
      "z": 9,
      "name": "Rock_Shale_Brick"
    },
    {
      "x": 2,
      "y": 8,
      "z": 10,
      "name": "Rock_Shale_Brick"
    },
    {
      "x": 2,
      "y": 8,
      "z": 11,
      "name": "Rock_Shale_Brick"
    },
    {
      "x": 2,
      "y": 8,
      "z": 12,
      "name": "Rock_Shale_Brick"
    },
    {
      "x": 2,
      "y": 8,
      "z": 13,
      "name": "Rock_Shale_Brick"
    },
    {
      "x": 3,
      "y": 8,
      "z": 3,
      "name": "Rock_Shale_Brick"
    },
    {
      "x": 3,
      "y": 8,
      "z": 4,
      "name": "Wood_Softwood_Planks"
    },
    {
      "x": 3,
      "y": 8,
      "z": 5,
      "name": "Wood_Softwood_Planks"
    },
    {
      "x": 3,
      "y": 8,
      "z": 6,
      "name": "Wood_Softwood_Planks"
    },
    {
      "x": 3,
      "y": 8,
      "z": 7,
      "name": "Wood_Softwood_Planks"
    },
    {
      "x": 3,
      "y": 8,
      "z": 8,
      "name": "Wood_Softwood_Planks"
    },
    {
      "x": 3,
      "y": 8,
      "z": 9,
      "name": "Wood_Softwood_Planks"
    },
    {
      "x": 3,
      "y": 8,
      "z": 10,
      "name": "Wood_Softwood_Planks"
    },
    {
      "x": 3,
      "y": 8,
      "z": 11,
      "name": "Wood_Softwood_Planks"
    },
    {
      "x": 3,
      "y": 8,
      "z": 12,
      "name": "Wood_Softwood_Planks"
    },
    {
      "x": 3,
      "y": 8,
      "z": 13,
      "name": "Rock_Shale_Brick"
    },
    {
      "x": 4,
      "y": 8,
      "z": 3,
      "name": "Rock_Shale_Brick"
    },
    {
      "x": 4,
      "y": 8,
      "z": 4,
      "name": "Wood_Softwood_Planks"
    },
    {
      "x": 4,
      "y": 8,
      "z": 5,
      "name": "Wood_Softwood_Planks"
    },
    {
      "x": 4,
      "y": 8,
      "z": 6,
      "name": "Wood_Softwood_Planks"
    },
    {
      "x": 4,
      "y": 8,
      "z": 7,
      "name": "Wood_Softwood_Planks"
    },
    {
      "x": 4,
      "y": 8,
      "z": 8,
      "name": "Wood_Softwood_Planks"
    },
    {
      "x": 4,
      "y": 8,
      "z": 9,
      "name": "Wood_Softwood_Planks"
    },
    {
      "x": 4,
      "y": 8,
      "z": 10,
      "name": "Wood_Softwood_Planks"
    },
    {
      "x": 4,
      "y": 8,
      "z": 11,
      "name": "Wood_Softwood_Planks"
    },
    {
      "x": 4,
      "y": 8,
      "z": 12,
      "name": "Wood_Softwood_Planks"
    },
    {
      "x": 4,
      "y": 8,
      "z": 13,
      "name": "Rock_Shale_Brick"
    },
    {
      "x": 5,
      "y": 8,
      "z": 3,
      "name": "Rock_Shale_Brick"
    },
    {
      "x": 5,
      "y": 8,
      "z": 4,
      "name": "Wood_Softwood_Planks"
    },
    {
      "x": 5,
      "y": 8,
      "z": 5,
      "name": "Wood_Softwood_Planks"
    },
    {
      "x": 5,
      "y": 8,
      "z": 6,
      "name": "Wood_Softwood_Planks"
    },
    {
      "x": 5,
      "y": 8,
      "z": 7,
      "name": "Wood_Softwood_Planks"
    },
    {
      "x": 5,
      "y": 8,
      "z": 8,
      "name": "Wood_Softwood_Planks"
    },
    {
      "x": 5,
      "y": 8,
      "z": 9,
      "name": "Wood_Softwood_Planks"
    },
    {
      "x": 5,
      "y": 8,
      "z": 10,
      "name": "Wood_Softwood_Planks"
    },
    {
      "x": 5,
      "y": 8,
      "z": 11,
      "name": "Wood_Softwood_Planks"
    },
    {
      "x": 5,
      "y": 8,
      "z": 12,
      "name": "Wood_Softwood_Planks"
    },
    {
      "x": 5,
      "y": 8,
      "z": 13,
      "name": "Rock_Shale_Brick"
    },
    {
      "x": 6,
      "y": 8,
      "z": 3,
      "name": "Rock_Shale_Brick"
    },
    {
      "x": 6,
      "y": 8,
      "z": 4,
      "name": "Wood_Softwood_Planks"
    },
    {
      "x": 6,
      "y": 8,
      "z": 5,
      "name": "Wood_Softwood_Planks"
    },
    {
      "x": 6,
      "y": 8,
      "z": 6,
      "name": "Wood_Softwood_Planks"
    },
    {
      "x": 6,
      "y": 8,
      "z": 7,
      "name": "Wood_Softwood_Planks"
    },
    {
      "x": 6,
      "y": 8,
      "z": 8,
      "name": "Wood_Softwood_Planks"
    },
    {
      "x": 6,
      "y": 8,
      "z": 9,
      "name": "Wood_Softwood_Planks"
    },
    {
      "x": 6,
      "y": 8,
      "z": 10,
      "name": "Wood_Softwood_Planks"
    },
    {
      "x": 6,
      "y": 8,
      "z": 11,
      "name": "Wood_Softwood_Planks"
    },
    {
      "x": 6,
      "y": 8,
      "z": 12,
      "name": "Wood_Softwood_Planks"
    },
    {
      "x": 6,
      "y": 8,
      "z": 13,
      "name": "Rock_Shale_Brick"
    },
    {
      "x": 7,
      "y": 8,
      "z": 3,
      "name": "Rock_Shale_Brick"
    },
    {
      "x": 7,
      "y": 8,
      "z": 4,
      "name": "Wood_Softwood_Planks"
    },
    {
      "x": 7,
      "y": 8,
      "z": 5,
      "name": "Wood_Softwood_Planks"
    },
    {
      "x": 7,
      "y": 8,
      "z": 6,
      "name": "Wood_Softwood_Planks"
    },
    {
      "x": 7,
      "y": 8,
      "z": 7,
      "name": "Wood_Softwood_Planks"
    },
    {
      "x": 7,
      "y": 8,
      "z": 8,
      "name": "Wood_Softwood_Planks"
    },
    {
      "x": 7,
      "y": 8,
      "z": 9,
      "name": "Wood_Softwood_Planks"
    },
    {
      "x": 7,
      "y": 8,
      "z": 10,
      "name": "Wood_Softwood_Planks"
    },
    {
      "x": 7,
      "y": 8,
      "z": 11,
      "name": "Wood_Softwood_Planks"
    },
    {
      "x": 7,
      "y": 8,
      "z": 12,
      "name": "Wood_Softwood_Planks"
    },
    {
      "x": 7,
      "y": 8,
      "z": 13,
      "name": "Rock_Shale_Brick"
    },
    {
      "x": 8,
      "y": 8,
      "z": 3,
      "name": "Rock_Shale_Brick"
    },
    {
      "x": 8,
      "y": 8,
      "z": 4,
      "name": "Wood_Softwood_Planks"
    },
    {
      "x": 8,
      "y": 8,
      "z": 5,
      "name": "Wood_Softwood_Planks"
    },
    {
      "x": 8,
      "y": 8,
      "z": 6,
      "name": "Wood_Softwood_Planks"
    },
    {
      "x": 8,
      "y": 8,
      "z": 7,
      "name": "Wood_Softwood_Planks"
    },
    {
      "x": 8,
      "y": 8,
      "z": 8,
      "name": "Wood_Softwood_Planks"
    },
    {
      "x": 8,
      "y": 8,
      "z": 9,
      "name": "Wood_Softwood_Planks"
    },
    {
      "x": 8,
      "y": 8,
      "z": 10,
      "name": "Wood_Softwood_Planks"
    },
    {
      "x": 8,
      "y": 8,
      "z": 11,
      "name": "Wood_Softwood_Planks"
    },
    {
      "x": 8,
      "y": 8,
      "z": 12,
      "name": "Wood_Softwood_Planks"
    },
    {
      "x": 8,
      "y": 8,
      "z": 13,
      "name": "Rock_Shale_Brick"
    },
    {
      "x": 9,
      "y": 8,
      "z": 3,
      "name": "Rock_Shale_Brick"
    },
    {
      "x": 9,
      "y": 8,
      "z": 4,
      "name": "Wood_Softwood_Planks"
    },
    {
      "x": 9,
      "y": 8,
      "z": 5,
      "name": "Wood_Softwood_Planks"
    },
    {
      "x": 9,
      "y": 8,
      "z": 6,
      "name": "Wood_Softwood_Planks"
    },
    {
      "x": 9,
      "y": 8,
      "z": 7,
      "name": "Wood_Softwood_Planks"
    },
    {
      "x": 9,
      "y": 8,
      "z": 8,
      "name": "Wood_Softwood_Planks"
    },
    {
      "x": 9,
      "y": 8,
      "z": 9,
      "name": "Wood_Softwood_Planks"
    },
    {
      "x": 9,
      "y": 8,
      "z": 10,
      "name": "Wood_Softwood_Planks"
    },
    {
      "x": 9,
      "y": 8,
      "z": 11,
      "name": "Wood_Softwood_Planks"
    },
    {
      "x": 9,
      "y": 8,
      "z": 12,
      "name": "Wood_Softwood_Planks"
    },
    {
      "x": 9,
      "y": 8,
      "z": 13,
      "name": "Rock_Shale_Brick"
    },
    {
      "x": 10,
      "y": 8,
      "z": 3,
      "name": "Rock_Shale_Brick"
    },
    {
      "x": 10,
      "y": 8,
      "z": 4,
      "name": "Wood_Softwood_Planks"
    },
    {
      "x": 10,
      "y": 8,
      "z": 9,
      "name": "Wood_Softwood_Planks"
    },
    {
      "x": 10,
      "y": 8,
      "z": 10,
      "name": "Wood_Softwood_Planks"
    },
    {
      "x": 10,
      "y": 8,
      "z": 11,
      "name": "Wood_Softwood_Planks"
    },
    {
      "x": 10,
      "y": 8,
      "z": 12,
      "name": "Wood_Softwood_Planks"
    },
    {
      "x": 10,
      "y": 8,
      "z": 13,
      "name": "Rock_Shale_Brick"
    },
    {
      "x": 11,
      "y": 8,
      "z": 3,
      "name": "Rock_Shale_Brick"
    },
    {
      "x": 11,
      "y": 8,
      "z": 4,
      "name": "Wood_Softwood_Planks"
    },
    {
      "x": 11,
      "y": 8,
      "z": 9,
      "name": "Wood_Softwood_Planks"
    },
    {
      "x": 11,
      "y": 8,
      "z": 10,
      "name": "Wood_Softwood_Planks"
    },
    {
      "x": 11,
      "y": 8,
      "z": 11,
      "name": "Wood_Softwood_Planks"
    },
    {
      "x": 11,
      "y": 8,
      "z": 12,
      "name": "Wood_Softwood_Planks"
    },
    {
      "x": 11,
      "y": 8,
      "z": 13,
      "name": "Rock_Shale_Brick"
    },
    {
      "x": 12,
      "y": 8,
      "z": 3,
      "name": "Rock_Shale_Brick"
    },
    {
      "x": 12,
      "y": 8,
      "z": 4,
      "name": "Rock_Shale_Brick"
    },
    {
      "x": 12,
      "y": 8,
      "z": 5,
      "name": "Rock_Shale_Brick"
    },
    {
      "x": 12,
      "y": 8,
      "z": 6,
      "name": "Rock_Shale_Brick"
    },
    {
      "x": 12,
      "y": 8,
      "z": 7,
      "name": "Rock_Shale_Brick"
    },
    {
      "x": 12,
      "y": 8,
      "z": 8,
      "name": "Rock_Shale_Brick"
    },
    {
      "x": 12,
      "y": 8,
      "z": 9,
      "name": "Rock_Shale_Brick"
    },
    {
      "x": 12,
      "y": 8,
      "z": 10,
      "name": "Rock_Shale_Brick"
    },
    {
      "x": 12,
      "y": 8,
      "z": 11,
      "name": "Rock_Shale_Brick"
    },
    {
      "x": 12,
      "y": 8,
      "z": 12,
      "name": "Rock_Shale_Brick"
    },
    {
      "x": 12,
      "y": 8,
      "z": 13,
      "name": "Rock_Shale_Brick"
    },
    {
      "x": 1,
      "y": 8,
      "z": 2,
      "name": "Rock_Shale_Brick"
    },
    {
      "x": 1,
      "y": 8,
      "z": 3,
      "name": "Rock_Shale_Brick"
    },
    {
      "x": 1,
      "y": 8,
      "z": 4,
      "name": "Rock_Shale_Brick"
    },
    {
      "x": 2,
      "y": 8,
      "z": 2,
      "name": "Rock_Shale_Brick"
    },
    {
      "x": 3,
      "y": 8,
      "z": 2,
      "name": "Rock_Shale_Brick"
    },
    {
      "x": 1,
      "y": 8,
      "z": 12,
      "name": "Rock_Shale_Brick"
    },
    {
      "x": 1,
      "y": 8,
      "z": 13,
      "name": "Rock_Shale_Brick"
    },
    {
      "x": 1,
      "y": 8,
      "z": 14,
      "name": "Rock_Shale_Brick"
    },
    {
      "x": 2,
      "y": 8,
      "z": 14,
      "name": "Rock_Shale_Brick"
    },
    {
      "x": 3,
      "y": 8,
      "z": 14,
      "name": "Rock_Shale_Brick"
    },
    {
      "x": 11,
      "y": 8,
      "z": 2,
      "name": "Rock_Shale_Brick"
    },
    {
      "x": 12,
      "y": 8,
      "z": 2,
      "name": "Rock_Shale_Brick"
    },
    {
      "x": 13,
      "y": 8,
      "z": 2,
      "name": "Rock_Shale_Brick"
    },
    {
      "x": 13,
      "y": 8,
      "z": 3,
      "name": "Rock_Shale_Brick"
    },
    {
      "x": 13,
      "y": 8,
      "z": 4,
      "name": "Rock_Shale_Brick"
    },
    {
      "x": 11,
      "y": 8,
      "z": 14,
      "name": "Rock_Shale_Brick"
    },
    {
      "x": 12,
      "y": 8,
      "z": 14,
      "name": "Rock_Shale_Brick"
    },
    {
      "x": 13,
      "y": 8,
      "z": 12,
      "name": "Rock_Shale_Brick"
    },
    {
      "x": 13,
      "y": 8,
      "z": 13,
      "name": "Rock_Shale_Brick"
    },
    {
      "x": 13,
      "y": 8,
      "z": 14,
      "name": "Rock_Shale_Brick"
    },
    {
      "x": 2,
      "y": 9,
      "z": 3,
      "name": "Rock_Shale_Brick_Pillar_Base"
    },
    {
      "x": 2,
      "y": 9,
      "z": 4,
      "name": "Rock_Shale_Cobble"
    },
    {
      "x": 2,
      "y": 9,
      "z": 5,
      "name": "Rock_Shale_Cobble"
    },
    {
      "x": 2,
      "y": 9,
      "z": 6,
      "name": "Rock_Shale_Cobble"
    },
    {
      "x": 2,
      "y": 9,
      "z": 7,
      "name": "Rock_Shale_Cobble"
    },
    {
      "x": 2,
      "y": 9,
      "z": 8,
      "name": "Rock_Shale_Cobble"
    },
    {
      "x": 2,
      "y": 9,
      "z": 9,
      "name": "Rock_Shale_Cobble"
    },
    {
      "x": 2,
      "y": 9,
      "z": 10,
      "name": "Rock_Shale_Cobble"
    },
    {
      "x": 2,
      "y": 9,
      "z": 11,
      "name": "Rock_Shale_Cobble"
    },
    {
      "x": 2,
      "y": 9,
      "z": 12,
      "name": "Rock_Shale_Cobble"
    },
    {
      "x": 2,
      "y": 9,
      "z": 13,
      "name": "Rock_Shale_Brick_Pillar_Base"
    },
    {
      "x": 3,
      "y": 9,
      "z": 3,
      "name": "Rock_Shale_Cobble"
    },
    {
      "x": 3,
      "y": 9,
      "z": 13,
      "name": "Rock_Shale_Cobble"
    },
    {
      "x": 4,
      "y": 9,
      "z": 3,
      "name": "Rock_Shale_Cobble"
    },
    {
      "x": 4,
      "y": 9,
      "z": 13,
      "name": "Rock_Shale_Cobble"
    },
    {
      "x": 5,
      "y": 9,
      "z": 3,
      "name": "Rock_Shale_Cobble"
    },
    {
      "x": 5,
      "y": 9,
      "z": 13,
      "name": "Rock_Shale_Cobble"
    },
    {
      "x": 6,
      "y": 9,
      "z": 3,
      "name": "Rock_Shale_Cobble"
    },
    {
      "x": 6,
      "y": 9,
      "z": 13,
      "name": "Rock_Shale_Cobble"
    },
    {
      "x": 7,
      "y": 9,
      "z": 3,
      "name": "Rock_Shale_Cobble"
    },
    {
      "x": 7,
      "y": 9,
      "z": 13,
      "name": "Rock_Shale_Cobble"
    },
    {
      "x": 8,
      "y": 9,
      "z": 3,
      "name": "Rock_Shale_Cobble"
    },
    {
      "x": 8,
      "y": 9,
      "z": 13,
      "name": "Rock_Shale_Cobble"
    },
    {
      "x": 9,
      "y": 9,
      "z": 3,
      "name": "Rock_Shale_Cobble"
    },
    {
      "x": 9,
      "y": 9,
      "z": 13,
      "name": "Rock_Shale_Cobble"
    },
    {
      "x": 10,
      "y": 9,
      "z": 3,
      "name": "Rock_Shale_Cobble"
    },
    {
      "x": 10,
      "y": 9,
      "z": 13,
      "name": "Rock_Shale_Cobble"
    },
    {
      "x": 11,
      "y": 9,
      "z": 3,
      "name": "Rock_Shale_Cobble"
    },
    {
      "x": 11,
      "y": 9,
      "z": 13,
      "name": "Rock_Shale_Cobble"
    },
    {
      "x": 12,
      "y": 9,
      "z": 3,
      "name": "Rock_Shale_Brick_Pillar_Base"
    },
    {
      "x": 12,
      "y": 9,
      "z": 4,
      "name": "Rock_Shale_Cobble"
    },
    {
      "x": 12,
      "y": 9,
      "z": 5,
      "name": "Rock_Shale_Cobble"
    },
    {
      "x": 12,
      "y": 9,
      "z": 6,
      "name": "Rock_Shale_Cobble"
    },
    {
      "x": 12,
      "y": 9,
      "z": 7,
      "name": "Rock_Shale_Cobble"
    },
    {
      "x": 12,
      "y": 9,
      "z": 8,
      "name": "Rock_Shale_Cobble"
    },
    {
      "x": 12,
      "y": 9,
      "z": 9,
      "name": "Rock_Shale_Cobble"
    },
    {
      "x": 12,
      "y": 9,
      "z": 10,
      "name": "Rock_Shale_Cobble"
    },
    {
      "x": 12,
      "y": 9,
      "z": 11,
      "name": "Rock_Shale_Cobble"
    },
    {
      "x": 12,
      "y": 9,
      "z": 12,
      "name": "Rock_Shale_Cobble"
    },
    {
      "x": 12,
      "y": 9,
      "z": 13,
      "name": "Rock_Shale_Brick_Pillar_Base"
    },
    {
      "x": 1,
      "y": 9,
      "z": 2,
      "name": "Rock_Shale_Brick_Pillar_Base"
    },
    {
      "x": 1,
      "y": 9,
      "z": 3,
      "name": "Rock_Shale_Cobble"
    },
    {
      "x": 1,
      "y": 9,
      "z": 4,
      "name": "Rock_Shale_Cobble"
    },
    {
      "x": 2,
      "y": 9,
      "z": 2,
      "name": "Rock_Shale_Cobble"
    },
    {
      "x": 3,
      "y": 9,
      "z": 2,
      "name": "Rock_Shale_Cobble"
    },
    {
      "x": 1,
      "y": 9,
      "z": 12,
      "name": "Rock_Shale_Cobble"
    },
    {
      "x": 1,
      "y": 9,
      "z": 13,
      "name": "Rock_Shale_Cobble"
    },
    {
      "x": 1,
      "y": 9,
      "z": 14,
      "name": "Rock_Shale_Brick_Pillar_Base"
    },
    {
      "x": 2,
      "y": 9,
      "z": 14,
      "name": "Rock_Shale_Cobble"
    },
    {
      "x": 3,
      "y": 9,
      "z": 14,
      "name": "Rock_Shale_Cobble"
    },
    {
      "x": 11,
      "y": 9,
      "z": 2,
      "name": "Rock_Shale_Cobble"
    },
    {
      "x": 12,
      "y": 9,
      "z": 2,
      "name": "Rock_Shale_Cobble"
    },
    {
      "x": 13,
      "y": 9,
      "z": 2,
      "name": "Rock_Shale_Brick_Pillar_Base"
    },
    {
      "x": 13,
      "y": 9,
      "z": 3,
      "name": "Rock_Shale_Cobble"
    },
    {
      "x": 13,
      "y": 9,
      "z": 4,
      "name": "Rock_Shale_Cobble"
    },
    {
      "x": 11,
      "y": 9,
      "z": 14,
      "name": "Rock_Shale_Cobble"
    },
    {
      "x": 12,
      "y": 9,
      "z": 14,
      "name": "Rock_Shale_Cobble"
    },
    {
      "x": 13,
      "y": 9,
      "z": 12,
      "name": "Rock_Shale_Cobble"
    },
    {
      "x": 13,
      "y": 9,
      "z": 13,
      "name": "Rock_Shale_Cobble"
    },
    {
      "x": 13,
      "y": 9,
      "z": 14,
      "name": "Rock_Shale_Brick_Pillar_Base"
    },
    {
      "x": 2,
      "y": 10,
      "z": 3,
      "name": "Rock_Shale_Brick_Pillar_Base"
    },
    {
      "x": 2,
      "y": 10,
      "z": 4,
      "name": "Rock_Shale_Cobble"
    },
    {
      "x": 2,
      "y": 10,
      "z": 5,
      "name": "Rock_Shale_Cobble"
    },
    {
      "x": 2,
      "y": 10,
      "z": 7,
      "name": "Rock_Shale_Cobble"
    },
    {
      "x": 2,
      "y": 10,
      "z": 8,
      "name": "Rock_Shale_Cobble"
    },
    {
      "x": 2,
      "y": 10,
      "z": 9,
      "name": "Rock_Shale_Cobble"
    },
    {
      "x": 2,
      "y": 10,
      "z": 11,
      "name": "Rock_Shale_Cobble"
    },
    {
      "x": 2,
      "y": 10,
      "z": 12,
      "name": "Rock_Shale_Cobble"
    },
    {
      "x": 2,
      "y": 10,
      "z": 13,
      "name": "Rock_Shale_Brick_Pillar_Base"
    },
    {
      "x": 3,
      "y": 10,
      "z": 3,
      "name": "Rock_Shale_Cobble"
    },
    {
      "x": 3,
      "y": 10,
      "z": 13,
      "name": "Rock_Shale_Cobble"
    },
    {
      "x": 4,
      "y": 10,
      "z": 3,
      "name": "Rock_Shale_Cobble"
    },
    {
      "x": 4,
      "y": 10,
      "z": 13,
      "name": "Rock_Shale_Cobble"
    },
    {
      "x": 6,
      "y": 10,
      "z": 3,
      "name": "Rock_Shale_Cobble"
    },
    {
      "x": 6,
      "y": 10,
      "z": 13,
      "name": "Rock_Shale_Cobble"
    },
    {
      "x": 7,
      "y": 10,
      "z": 3,
      "name": "Rock_Shale_Cobble"
    },
    {
      "x": 7,
      "y": 10,
      "z": 13,
      "name": "Rock_Shale_Cobble"
    },
    {
      "x": 8,
      "y": 10,
      "z": 3,
      "name": "Rock_Shale_Cobble"
    },
    {
      "x": 8,
      "y": 10,
      "z": 13,
      "name": "Rock_Shale_Cobble"
    },
    {
      "x": 10,
      "y": 10,
      "z": 3,
      "name": "Rock_Shale_Cobble"
    },
    {
      "x": 10,
      "y": 10,
      "z": 13,
      "name": "Rock_Shale_Cobble"
    },
    {
      "x": 11,
      "y": 10,
      "z": 3,
      "name": "Rock_Shale_Cobble"
    },
    {
      "x": 11,
      "y": 10,
      "z": 13,
      "name": "Rock_Shale_Cobble"
    },
    {
      "x": 12,
      "y": 10,
      "z": 3,
      "name": "Rock_Shale_Brick_Pillar_Base"
    },
    {
      "x": 12,
      "y": 10,
      "z": 4,
      "name": "Rock_Shale_Cobble"
    },
    {
      "x": 12,
      "y": 10,
      "z": 5,
      "name": "Rock_Shale_Cobble"
    },
    {
      "x": 12,
      "y": 10,
      "z": 7,
      "name": "Rock_Shale_Cobble"
    },
    {
      "x": 12,
      "y": 10,
      "z": 8,
      "name": "Rock_Shale_Cobble"
    },
    {
      "x": 12,
      "y": 10,
      "z": 9,
      "name": "Rock_Shale_Cobble"
    },
    {
      "x": 12,
      "y": 10,
      "z": 11,
      "name": "Rock_Shale_Cobble"
    },
    {
      "x": 12,
      "y": 10,
      "z": 12,
      "name": "Rock_Shale_Cobble"
    },
    {
      "x": 12,
      "y": 10,
      "z": 13,
      "name": "Rock_Shale_Brick_Pillar_Base"
    },
    {
      "x": 1,
      "y": 10,
      "z": 2,
      "name": "Rock_Shale_Brick_Pillar_Base"
    },
    {
      "x": 1,
      "y": 10,
      "z": 3,
      "name": "Rock_Shale_Cobble"
    },
    {
      "x": 1,
      "y": 10,
      "z": 4,
      "name": "Rock_Shale_Cobble"
    },
    {
      "x": 2,
      "y": 10,
      "z": 2,
      "name": "Rock_Shale_Cobble"
    },
    {
      "x": 3,
      "y": 10,
      "z": 2,
      "name": "Rock_Shale_Cobble"
    },
    {
      "x": 1,
      "y": 10,
      "z": 12,
      "name": "Rock_Shale_Cobble"
    },
    {
      "x": 1,
      "y": 10,
      "z": 13,
      "name": "Rock_Shale_Cobble"
    },
    {
      "x": 1,
      "y": 10,
      "z": 14,
      "name": "Rock_Shale_Brick_Pillar_Base"
    },
    {
      "x": 2,
      "y": 10,
      "z": 14,
      "name": "Rock_Shale_Cobble"
    },
    {
      "x": 3,
      "y": 10,
      "z": 14,
      "name": "Rock_Shale_Cobble"
    },
    {
      "x": 11,
      "y": 10,
      "z": 2,
      "name": "Rock_Shale_Cobble"
    },
    {
      "x": 12,
      "y": 10,
      "z": 2,
      "name": "Rock_Shale_Cobble"
    },
    {
      "x": 13,
      "y": 10,
      "z": 2,
      "name": "Rock_Shale_Brick_Pillar_Base"
    },
    {
      "x": 13,
      "y": 10,
      "z": 3,
      "name": "Rock_Shale_Cobble"
    },
    {
      "x": 13,
      "y": 10,
      "z": 4,
      "name": "Rock_Shale_Cobble"
    },
    {
      "x": 11,
      "y": 10,
      "z": 14,
      "name": "Rock_Shale_Cobble"
    },
    {
      "x": 12,
      "y": 10,
      "z": 14,
      "name": "Rock_Shale_Cobble"
    },
    {
      "x": 13,
      "y": 10,
      "z": 12,
      "name": "Rock_Shale_Cobble"
    },
    {
      "x": 13,
      "y": 10,
      "z": 13,
      "name": "Rock_Shale_Cobble"
    },
    {
      "x": 13,
      "y": 10,
      "z": 14,
      "name": "Rock_Shale_Brick_Pillar_Base"
    },
    {
      "x": 2,
      "y": 11,
      "z": 3,
      "name": "Rock_Shale_Brick_Pillar_Base"
    },
    {
      "x": 2,
      "y": 11,
      "z": 4,
      "name": "Rock_Shale_Cobble"
    },
    {
      "x": 2,
      "y": 11,
      "z": 5,
      "name": "Rock_Shale_Cobble"
    },
    {
      "x": 2,
      "y": 11,
      "z": 7,
      "name": "Rock_Shale_Cobble"
    },
    {
      "x": 2,
      "y": 11,
      "z": 8,
      "name": "Rock_Shale_Cobble"
    },
    {
      "x": 2,
      "y": 11,
      "z": 9,
      "name": "Rock_Shale_Cobble"
    },
    {
      "x": 2,
      "y": 11,
      "z": 11,
      "name": "Rock_Shale_Cobble"
    },
    {
      "x": 2,
      "y": 11,
      "z": 12,
      "name": "Rock_Shale_Cobble"
    },
    {
      "x": 2,
      "y": 11,
      "z": 13,
      "name": "Rock_Shale_Brick_Pillar_Base"
    },
    {
      "x": 3,
      "y": 11,
      "z": 3,
      "name": "Rock_Shale_Cobble"
    },
    {
      "x": 3,
      "y": 11,
      "z": 13,
      "name": "Rock_Shale_Cobble"
    },
    {
      "x": 4,
      "y": 11,
      "z": 3,
      "name": "Rock_Shale_Cobble"
    },
    {
      "x": 4,
      "y": 11,
      "z": 13,
      "name": "Rock_Shale_Cobble"
    },
    {
      "x": 6,
      "y": 11,
      "z": 3,
      "name": "Rock_Shale_Cobble"
    },
    {
      "x": 6,
      "y": 11,
      "z": 13,
      "name": "Rock_Shale_Cobble"
    },
    {
      "x": 7,
      "y": 11,
      "z": 3,
      "name": "Rock_Shale_Cobble"
    },
    {
      "x": 7,
      "y": 11,
      "z": 13,
      "name": "Rock_Shale_Cobble"
    },
    {
      "x": 8,
      "y": 11,
      "z": 3,
      "name": "Rock_Shale_Cobble"
    },
    {
      "x": 8,
      "y": 11,
      "z": 13,
      "name": "Rock_Shale_Cobble"
    },
    {
      "x": 10,
      "y": 11,
      "z": 3,
      "name": "Rock_Shale_Cobble"
    },
    {
      "x": 10,
      "y": 11,
      "z": 13,
      "name": "Rock_Shale_Cobble"
    },
    {
      "x": 11,
      "y": 11,
      "z": 3,
      "name": "Rock_Shale_Cobble"
    },
    {
      "x": 11,
      "y": 11,
      "z": 13,
      "name": "Rock_Shale_Cobble"
    },
    {
      "x": 12,
      "y": 11,
      "z": 3,
      "name": "Rock_Shale_Brick_Pillar_Base"
    },
    {
      "x": 12,
      "y": 11,
      "z": 4,
      "name": "Rock_Shale_Cobble"
    },
    {
      "x": 12,
      "y": 11,
      "z": 5,
      "name": "Rock_Shale_Cobble"
    },
    {
      "x": 12,
      "y": 11,
      "z": 7,
      "name": "Rock_Shale_Cobble"
    },
    {
      "x": 12,
      "y": 11,
      "z": 8,
      "name": "Rock_Shale_Cobble"
    },
    {
      "x": 12,
      "y": 11,
      "z": 9,
      "name": "Rock_Shale_Cobble"
    },
    {
      "x": 12,
      "y": 11,
      "z": 11,
      "name": "Rock_Shale_Cobble"
    },
    {
      "x": 12,
      "y": 11,
      "z": 12,
      "name": "Rock_Shale_Cobble"
    },
    {
      "x": 12,
      "y": 11,
      "z": 13,
      "name": "Rock_Shale_Brick_Pillar_Base"
    },
    {
      "x": 1,
      "y": 11,
      "z": 2,
      "name": "Rock_Shale_Brick_Pillar_Base"
    },
    {
      "x": 1,
      "y": 11,
      "z": 3,
      "name": "Rock_Shale_Cobble"
    },
    {
      "x": 1,
      "y": 11,
      "z": 4,
      "name": "Rock_Shale_Cobble"
    },
    {
      "x": 2,
      "y": 11,
      "z": 2,
      "name": "Rock_Shale_Cobble"
    },
    {
      "x": 3,
      "y": 11,
      "z": 2,
      "name": "Rock_Shale_Cobble"
    },
    {
      "x": 1,
      "y": 11,
      "z": 12,
      "name": "Rock_Shale_Cobble"
    },
    {
      "x": 1,
      "y": 11,
      "z": 13,
      "name": "Rock_Shale_Cobble"
    },
    {
      "x": 1,
      "y": 11,
      "z": 14,
      "name": "Rock_Shale_Brick_Pillar_Base"
    },
    {
      "x": 2,
      "y": 11,
      "z": 14,
      "name": "Rock_Shale_Cobble"
    },
    {
      "x": 3,
      "y": 11,
      "z": 14,
      "name": "Rock_Shale_Cobble"
    },
    {
      "x": 11,
      "y": 11,
      "z": 2,
      "name": "Rock_Shale_Cobble"
    },
    {
      "x": 12,
      "y": 11,
      "z": 2,
      "name": "Rock_Shale_Cobble"
    },
    {
      "x": 13,
      "y": 11,
      "z": 2,
      "name": "Rock_Shale_Brick_Pillar_Base"
    },
    {
      "x": 13,
      "y": 11,
      "z": 3,
      "name": "Rock_Shale_Cobble"
    },
    {
      "x": 13,
      "y": 11,
      "z": 4,
      "name": "Rock_Shale_Cobble"
    },
    {
      "x": 11,
      "y": 11,
      "z": 14,
      "name": "Rock_Shale_Cobble"
    },
    {
      "x": 12,
      "y": 11,
      "z": 14,
      "name": "Rock_Shale_Cobble"
    },
    {
      "x": 13,
      "y": 11,
      "z": 12,
      "name": "Rock_Shale_Cobble"
    },
    {
      "x": 13,
      "y": 11,
      "z": 13,
      "name": "Rock_Shale_Cobble"
    },
    {
      "x": 13,
      "y": 11,
      "z": 14,
      "name": "Rock_Shale_Brick_Pillar_Base"
    },
    {
      "x": 2,
      "y": 12,
      "z": 3,
      "name": "Rock_Shale_Brick_Pillar_Base"
    },
    {
      "x": 2,
      "y": 12,
      "z": 4,
      "name": "Rock_Shale_Cobble"
    },
    {
      "x": 2,
      "y": 12,
      "z": 5,
      "name": "Rock_Shale_Cobble"
